Workbook

Sheet table (2)
B2: Макро эдийн засгийн нөхцөл байдал - 25M7
M3: 21Q4 | N3: 22Q4 | O3: 23Q4 | P3: 24Q4 | Q3: 25Q1 | R3: 25Q2 | S3: 25Q3
D4: 21Y | E4: 22Y | F4: 23Y | G4: 24Y | H4: 25Q1 | I4: 25Q2 | J4: 25Q3 | M4: 21M12 | N4: 22M12 | O4: 23M12 | P4: 24M12 | Q4: 25M03 | R4: 25M06 | S4: 25M09 | U4: 25M03 | V4: 25M06 | W4: 25M07
B6: Инфляци | C6: %, жилийн (YoY) | D6: =M6 -> 13.826662 | E6: =N6 -> 13.243298 | F6: =O6 -> 7.9239441 | G6: =P6 -> 8.3598213 | H6: =Q6 -> 9.1020943 | I6: =R6 -> 8.186335 | J6: =S6 -> 9.0299817 | L6: cpi_yoy | M6: =INDEX(m!$B$2:$AX$50,MATCH('table (2)'!$L6,m!$A$2:$A$50,0),MATCH('table (2)'!M$4,m!$B$1:$AX$1,0)) -> 13.826662 | N6: =INDEX(m!$B$2:$AX$50,MATCH('table (2)'!$L6,m!$A$2:$A$50,0),MATCH('table (2)'!N$4,m!$B$1:$AX$1,0)) -> 13.243298 | O6: =INDEX(m!$B$2:$AX$50,MATCH('table (2)'!$L6,m!$A$2:$A$50,0),MATCH('table (2)'!O$4,m!$B$1:$AX$1,0)) -> 7.9239441 | P6: =INDEX(m!$B$2:$AX$50,MATCH('table (2)'!$L6,m!$A$2:$A$50,0),MATCH('table (2)'!P$4,m!$B$1:$AX$1,0)) -> 8.3598213 | Q6: =INDEX(m!$B$2:$AX$50,MATCH('table (2)'!$L6,m!$A$2:$A$50,0),MATCH('table (2)'!Q$4,m!$B$1:$AX$1,0)) -> 9.1020943 | R6: =INDEX(m!$B$2:$AX$50,MATCH('table (2)'!$L6,m!$A$2:$A$50,0),MATCH('table (2)'!R$4,m!$B$1:$AX$1,0)) -> 8.186335 | S6: =INDEX(m!$B$2:$AZ$50,MATCH('table (2)'!$L6,m!$A$2:$A$50,0),MATCH('table (2)'!S$4,m!$B$1:$AZ$1,0)) -> 9.0299817 | U6: 9.1020943 | V6: 8.186335 | W6: 8.0997478
C7: %, улирлын (QoQ) | I7: =R7 -> 3.1141627 | J7: =S7 -> 7.0592549 | L7: cpi_qoq | M7: =INDEX(m!$B$2:$AX$50,MATCH('table (2)'!$L7,m!$A$2:$A$50,0),MATCH('table (2)'!M$4,m!$B$1:$AX$1,0)) -> 15.683225 | N7: =INDEX(m!$B$2:$AX$50,MATCH('table (2)'!$L7,m!$A$2:$A$50,0),MATCH('table (2)'!N$4,m!$B$1:$AX$1,0)) -> 13.55178 | O7: =INDEX(m!$B$2:$AX$50,MATCH('table (2)'!$L7,m!$A$2:$A$50,0),MATCH('table (2)'!O$4,m!$B$1:$AX$1,0)) -> 5.5238011 | P7: =INDEX(m!$B$2:$AX$50,MATCH('table (2)'!$L7,m!$A$2:$A$50,0),MATCH('table (2)'!P$4,m!$B$1:$AX$1,0)) -> 13.263454 | Q7: =INDEX(m!$B$2:$AX$50,MATCH('table (2)'!$L7,m!$A$2:$A$50,0),MATCH('table (2)'!Q$4,m!$B$1:$AX$1,0)) -> 11.59796 | R7: =INDEX(m!$B$2:$AX$50,MATCH('table (2)'!$L7,m!$A$2:$A$50,0),MATCH('table (2)'!R$4,m!$B$1:$AX$1,0)) -> 3.1141627 | S7: =INDEX(m!$B$2:$AZ$50,MATCH('table (2)'!$L7,m!$A$2:$A$50,0),MATCH('table (2)'!S$4,m!$B$1:$AZ$1,0)) -> 7.0592549 | U7: 2.8994899 | V7: 0.77854068 | W7: 0.39314573
C8: %, улирлын (QoQ) | H8: =Q8 -> 11.59796 | I8: =R8 -> 3.1141627 | J8: =S8 -> 7.0592549 | L8: cpi_qoq | M8: =INDEX(m!$B$2:$AX$50,MATCH('table (2)'!$L8,m!$A$2:$A$50,0),MATCH('table (2)'!M$4,m!$B$1:$AX$1,0)) -> 15.683225 | N8: =INDEX(m!$B$2:$AX$50,MATCH('table (2)'!$L8,m!$A$2:$A$50,0),MATCH('table (2)'!N$4,m!$B$1:$AX$1,0)) -> 13.55178 | O8: =INDEX(m!$B$2:$AX$50,MATCH('table (2)'!$L8,m!$A$2:$A$50,0),MATCH('table (2)'!O$4,m!$B$1:$AX$1,0)) -> 5.5238011 | P8: =INDEX(m!$B$2:$AX$50,MATCH('table (2)'!$L8,m!$A$2:$A$50,0),MATCH('table (2)'!P$4,m!$B$1:$AX$1,0)) -> 13.263454 | Q8: =INDEX(m!$B$2:$AX$50,MATCH('table (2)'!$L8,m!$A$2:$A$50,0),MATCH('table (2)'!Q$4,m!$B$1:$AX$1,0)) -> 11.59796 | R8: =INDEX(m!$B$2:$AX$50,MATCH('table (2)'!$L8,m!$A$2:$A$50,0),MATCH('table (2)'!R$4,m!$B$1:$AX$1,0)) -> 3.1141627 | S8: =INDEX(m!$B$2:$AZ$50,MATCH('table (2)'!$L8,m!$A$2:$A$50,0),MATCH('table (2)'!S$4,m!$B$1:$AZ$1,0)) -> 7.0592549 | U8: 0.34988316 | V8: 0.23000865 | W8: -0.050507483
B9: Ам.доллар | D9: =M9 -> 2849.34 | E9: =N9 -> 3444.6 | F9: =O9 -> 3410.69 | G9: =P9 -> 3420.46 | H9: =Q9 -> 3487.61 | I9: =R9 -> 3580.94 | J9: =S9 -> 3594.64 | L9: usd_mnt | M9: =INDEX(m!$B$2:$AX$50,MATCH('table (2)'!$L9,m!$A$2:$A$50,0),MATCH('table (2)'!M$4,m!$B$1:$AX$1,0)) -> 2849.34 | N9: =INDEX(m!$B$2:$AX$50,MATCH('table (2)'!$L9,m!$A$2:$A$50,0),MATCH('table (2)'!N$4,m!$B$1:$AX$1,0)) -> 3444.6 | O9: =INDEX(m!$B$2:$AX$50,MATCH('table (2)'!$L9,m!$A$2:$A$50,0),MATCH('table (2)'!O$4,m!$B$1:$AX$1,0)) -> 3410.69 | P9: =INDEX(m!$B$2:$AX$50,MATCH('table (2)'!$L9,m!$A$2:$A$50,0),MATCH('table (2)'!P$4,m!$B$1:$AX$1,0)) -> 3420.46 | Q9: =INDEX(m!$B$2:$AX$50,MATCH('table (2)'!$L9,m!$A$2:$A$50,0),MATCH('table (2)'!Q$4,m!$B$1:$AX$1,0)) -> 3487.61 | R9: =INDEX(m!$B$2:$AX$50,MATCH('table (2)'!$L9,m!$A$2:$A$50,0),MATCH('table (2)'!R$4,m!$B$1:$AX$1,0)) -> 3580.94 | S9: =INDEX(m!$B$2:$AZ$50,MATCH('table (2)'!$L9,m!$A$2:$A$50,0),MATCH('table (2)'!S$4,m!$B$1:$AZ$1,0)) -> 3594.64 | U9: 3487.61 | V9: 3580.94 | W9: 3587.49
C10: %, жилийн (YoY) | D10: =M10 -> -0.01929899 | E10: =N10 -> 20.891154 | F10: =O10 -> -0.98443941 | G10: =P10 -> 0.2864523 | H10: =Q10 -> 3.3062894 | I10: =R10 -> 5.9120687 | J10: =S10 -> 6.3210418 | L10: usd_mnt_yoy | M10: =INDEX(m!$B$2:$AX$50,MATCH('table (2)'!$L10,m!$A$2:$A$50,0),MATCH('table (2)'!M$4,m!$B$1:$AX$1,0)) -> -0.01929899 | N10: =INDEX(m!$B$2:$AX$50,MATCH('table (2)'!$L10,m!$A$2:$A$50,0),MATCH('table (2)'!N$4,m!$B$1:$AX$1,0)) -> 20.891154 | O10: =INDEX(m!$B$2:$AX$50,MATCH('table (2)'!$L10,m!$A$2:$A$50,0),MATCH('table (2)'!O$4,m!$B$1:$AX$1,0)) -> -0.98443941 | P10: =INDEX(m!$B$2:$AX$50,MATCH('table (2)'!$L10,m!$A$2:$A$50,0),MATCH('table (2)'!P$4,m!$B$1:$AX$1,0)) -> 0.2864523 | Q10: =INDEX(m!$B$2:$AX$50,MATCH('table (2)'!$L10,m!$A$2:$A$50,0),MATCH('table (2)'!Q$4,m!$B$1:$AX$1,0)) -> 3.3062894 | R10: =INDEX(m!$B$2:$AX$50,MATCH('table (2)'!$L10,m!$A$2:$A$50,0),MATCH('table (2)'!R$4,m!$B$1:$AX$1,0)) -> 5.9120687 | S10: =INDEX(m!$B$2:$AZ$50,MATCH('table (2)'!$L10,m!$A$2:$A$50,0),MATCH('table (2)'!S$4,m!$B$1:$AZ$1,0)) -> 6.3210418 | U10: 3.3062894 | V10: 5.9120687 | W10: 6.1133279
C11: %, улирлын (QoQ) | I11: =R11 -> 10.704179 | J11: =S11 -> 1.5303244 | L11: usd_mnt_qoq | M11: =INDEX(m!$B$2:$AX$50,MATCH('table (2)'!$L11,m!$A$2:$A$50,0),MATCH('table (2)'!M$4,m!$B$1:$AX$1,0)) -> 0.01965464 | N11: =INDEX(m!$B$2:$AX$50,MATCH('table (2)'!$L11,m!$A$2:$A$50,0),MATCH('table (2)'!N$4,m!$B$1:$AX$1,0)) -> 13.390859 | O11: =INDEX(m!$B$2:$AX$50,MATCH('table (2)'!$L11,m!$A$2:$A$50,0),MATCH('table (2)'!O$4,m!$B$1:$AX$1,0)) -> -5.6435901 | P11: =INDEX(m!$B$2:$AX$50,MATCH('table (2)'!$L11,m!$A$2:$A$50,0),MATCH('table (2)'!P$4,m!$B$1:$AX$1,0)) -> 4.6768197 | Q11: =INDEX(m!$B$2:$AX$50,MATCH('table (2)'!$L11,m!$A$2:$A$50,0),MATCH('table (2)'!Q$4,m!$B$1:$AX$1,0)) -> 7.852745 | R11: =INDEX(m!$B$2:$AX$50,MATCH('table (2)'!$L11,m!$A$2:$A$50,0),MATCH('table (2)'!R$4,m!$B$1:$AX$1,0)) -> 10.704179 | S11: =INDEX(m!$B$2:$AZ$50,MATCH('table (2)'!$L11,m!$A$2:$A$50,0),MATCH('table (2)'!S$4,m!$B$1:$AZ$1,0)) -> 1.5303244 | U11: 1.9631862 | V11: 2.6760446 | W11: 0.46683955
C12: %, улирлын (QoQ) | H12: =Q12 -> 7.852745 | I12: =R12 -> 10.704179 | J12: =S12 -> 1.5303244 | L12: usd_mnt_qoq | M12: =INDEX(m!$B$2:$AX$50,MATCH('table (2)'!$L12,m!$A$2:$A$50,0),MATCH('table (2)'!M$4,m!$B$1:$AX$1,0)) -> 0.01965464 | N12: =INDEX(m!$B$2:$AX$50,MATCH('table (2)'!$L12,m!$A$2:$A$50,0),MATCH('table (2)'!N$4,m!$B$1:$AX$1,0)) -> 13.390859 | O12: =INDEX(m!$B$2:$AX$50,MATCH('table (2)'!$L12,m!$A$2:$A$50,0),MATCH('table (2)'!O$4,m!$B$1:$AX$1,0)) -> -5.6435901 | P12: =INDEX(m!$B$2:$AX$50,MATCH('table (2)'!$L12,m!$A$2:$A$50,0),MATCH('table (2)'!P$4,m!$B$1:$AX$1,0)) -> 4.6768197 | Q12: =INDEX(m!$B$2:$AX$50,MATCH('table (2)'!$L12,m!$A$2:$A$50,0),MATCH('table (2)'!Q$4,m!$B$1:$AX$1,0)) -> 7.852745 | R12: =INDEX(m!$B$2:$AX$50,MATCH('table (2)'!$L12,m!$A$2:$A$50,0),MATCH('table (2)'!R$4,m!$B$1:$AX$1,0)) -> 10.704179 | S12: =INDEX(m!$B$2:$AZ$50,MATCH('table (2)'!$L12,m!$A$2:$A$50,0),MATCH('table (2)'!S$4,m!$B$1:$AZ$1,0)) -> 1.5303244 | U12: 0.60723022 | V12: 0.19558192 | W12: 0.18291287
B13: Хятадын юань | D13: =M13 -> 446.96 | E13: =N13 -> 495.4 | F13: =O13 -> 480.01 | G13: =P13 -> 468.6 | H13: =Q13 -> 480.91 | I13: =R13 -> 499.76 | J13: =S13 -> 505.01 | L13: cny_mnt | M13: =INDEX(m!$B$2:$AX$50,MATCH('table (2)'!$L13,m!$A$2:$A$50,0),MATCH('table (2)'!M$4,m!$B$1:$AX$1,0)) -> 446.96 | N13: =INDEX(m!$B$2:$AX$50,MATCH('table (2)'!$L13,m!$A$2:$A$50,0),MATCH('table (2)'!N$4,m!$B$1:$AX$1,0)) -> 495.4 | O13: =INDEX(m!$B$2:$AX$50,MATCH('table (2)'!$L13,m!$A$2:$A$50,0),MATCH('table (2)'!O$4,m!$B$1:$AX$1,0)) -> 480.01 | P13: =INDEX(m!$B$2:$AX$50,MATCH('table (2)'!$L13,m!$A$2:$A$50,0),MATCH('table (2)'!P$4,m!$B$1:$AX$1,0)) -> 468.6 | Q13: =INDEX(m!$B$2:$AX$50,MATCH('table (2)'!$L13,m!$A$2:$A$50,0),MATCH('table (2)'!Q$4,m!$B$1:$AX$1,0)) -> 480.91 | R13: =INDEX(m!$B$2:$AX$50,MATCH('table (2)'!$L13,m!$A$2:$A$50,0),MATCH('table (2)'!R$4,m!$B$1:$AX$1,0)) -> 499.76 | S13: =INDEX(m!$B$2:$AZ$50,MATCH('table (2)'!$L13,m!$A$2:$A$50,0),MATCH('table (2)'!S$4,m!$B$1:$AZ$1,0)) -> 505.01 | U13: 480.91 | V13: 499.76 | W13: 498.81
C14: %, жилийн (YoY) | D14: =M14 -> 2.4597116 | E14: =N14 -> 10.837659 | F14: =O14 -> -3.1065805 | G14: =P14 -> -2.3770338 | H14: =Q14 -> 2.9102737 | I14: =R14 -> 7.4429204 | J14: =S14 -> 4.7521261 | L14: cny_mnt_yoy | M14: =INDEX(m!$B$2:$AX$50,MATCH('table (2)'!$L14,m!$A$2:$A$50,0),MATCH('table (2)'!M$4,m!$B$1:$AX$1,0)) -> 2.4597116 | N14: =INDEX(m!$B$2:$AX$50,MATCH('table (2)'!$L14,m!$A$2:$A$50,0),MATCH('table (2)'!N$4,m!$B$1:$AX$1,0)) -> 10.837659 | O14: =INDEX(m!$B$2:$AX$50,MATCH('table (2)'!$L14,m!$A$2:$A$50,0),MATCH('table (2)'!O$4,m!$B$1:$AX$1,0)) -> -3.1065805 | P14: =INDEX(m!$B$2:$AX$50,MATCH('table (2)'!$L14,m!$A$2:$A$50,0),MATCH('table (2)'!P$4,m!$B$1:$AX$1,0)) -> -2.3770338 | Q14: =INDEX(m!$B$2:$AX$50,MATCH('table (2)'!$L14,m!$A$2:$A$50,0),MATCH('table (2)'!Q$4,m!$B$1:$AX$1,0)) -> 2.9102737 | R14: =INDEX(m!$B$2:$AX$50,MATCH('table (2)'!$L14,m!$A$2:$A$50,0),MATCH('table (2)'!R$4,m!$B$1:$AX$1,0)) -> 7.4429204 | S14: =INDEX(m!$B$2:$AZ$50,MATCH('table (2)'!$L14,m!$A$2:$A$50,0),MATCH('table (2)'!S$4,m!$B$1:$AZ$1,0)) -> 4.7521261 | U14: 2.9102737 | V14: 7.4429204 | W14: 6.5537351
C15: %, улирлын (QoQ) | I15: =R15 -> 15.678609 | J15: =S15 -> 4.202017 | L15: cny_mnt_qoq | M15: =INDEX(m!$B$2:$AX$50,MATCH('table (2)'!$L15,m!$A$2:$A$50,0),MATCH('table (2)'!M$4,m!$B$1:$AX$1,0)) -> 5.5898367 | N15: =INDEX(m!$B$2:$AX$50,MATCH('table (2)'!$L15,m!$A$2:$A$50,0),MATCH('table (2)'!N$4,m!$B$1:$AX$1,0)) -> 28.40774 | O15: =INDEX(m!$B$2:$AX$50,MATCH('table (2)'!$L15,m!$A$2:$A$50,0),MATCH('table (2)'!O$4,m!$B$1:$AX$1,0)) -> 5.2341656 | P15: =INDEX(m!$B$2:$AX$50,MATCH('table (2)'!$L15,m!$A$2:$A$50,0),MATCH('table (2)'!P$4,m!$B$1:$AX$1,0)) -> -11.200996 | Q15: =INDEX(m!$B$2:$AX$50,MATCH('table (2)'!$L15,m!$A$2:$A$50,0),MATCH('table (2)'!Q$4,m!$B$1:$AX$1,0)) -> 10.507896 | R15: =INDEX(m!$B$2:$AX$50,MATCH('table (2)'!$L15,m!$A$2:$A$50,0),MATCH('table (2)'!R$4,m!$B$1:$AX$1,0)) -> 15.678609 | S15: =INDEX(m!$B$2:$AZ$50,MATCH('table (2)'!$L15,m!$A$2:$A$50,0),MATCH('table (2)'!S$4,m!$B$1:$AZ$1,0)) -> 4.202017 | U15: 2.626974 | V15: 3.9196523 | W15: 1.4707677
C16: %, улирлын (QoQ) | H16: =Q16 -> 10.507896 | I16: =R16 -> 15.678609 | J16: =S16 -> 4.202017 | L16: cny_mnt_qoq | M16: =INDEX(m!$B$2:$AX$50,MATCH('table (2)'!$L16,m!$A$2:$A$50,0),MATCH('table (2)'!M$4,m!$B$1:$AX$1,0)) -> 5.5898367 | N16: =INDEX(m!$B$2:$AX$50,MATCH('table (2)'!$L16,m!$A$2:$A$50,0),MATCH('table (2)'!N$4,m!$B$1:$AX$1,0)) -> 28.40774 | O16: =INDEX(m!$B$2:$AX$50,MATCH('table (2)'!$L16,m!$A$2:$A$50,0),MATCH('table (2)'!O$4,m!$B$1:$AX$1,0)) -> 5.2341656 | P16: =INDEX(m!$B$2:$AX$50,MATCH('table (2)'!$L16,m!$A$2:$A$50,0),MATCH('table (2)'!P$4,m!$B$1:$AX$1,0)) -> -11.200996 | Q16: =INDEX(m!$B$2:$AX$50,MATCH('table (2)'!$L16,m!$A$2:$A$50,0),MATCH('table (2)'!Q$4,m!$B$1:$AX$1,0)) -> 10.507896 | R16: =INDEX(m!$B$2:$AX$50,MATCH('table (2)'!$L16,m!$A$2:$A$50,0),MATCH('table (2)'!R$4,m!$B$1:$AX$1,0)) -> 15.678609 | S16: =INDEX(m!$B$2:$AZ$50,MATCH('table (2)'!$L16,m!$A$2:$A$50,0),MATCH('table (2)'!S$4,m!$B$1:$AZ$1,0)) -> 4.202017 | U16: 1.0527422 | V16: 0.62822165 | W16: -0.19009124
B17: Бодлогын хүү | C17: %, жилийн | D17: =M17 -> 6 | E17: =N17 -> 13 | F17: =O17 -> 13 | G17: =P17 -> 10 | H17: =Q17 -> 11.715064 | I17: =R17 -> 12 | J17: =S17 -> 12 | L17: rate_pol | M17: =INDEX(m!$B$2:$AX$50,MATCH('table (2)'!$L17,m!$A$2:$A$50,0),MATCH('table (2)'!M$4,m!$B$1:$AX$1,0)) -> 6 | N17: =INDEX(m!$B$2:$AX$50,MATCH('table (2)'!$L17,m!$A$2:$A$50,0),MATCH('table (2)'!N$4,m!$B$1:$AX$1,0)) -> 13 | O17: =INDEX(m!$B$2:$AX$50,MATCH('table (2)'!$L17,m!$A$2:$A$50,0),MATCH('table (2)'!O$4,m!$B$1:$AX$1,0)) -> 13 | P17: =INDEX(m!$B$2:$AX$50,MATCH('table (2)'!$L17,m!$A$2:$A$50,0),MATCH('table (2)'!P$4,m!$B$1:$AX$1,0)) -> 10 | Q17: =INDEX(m!$B$2:$AX$50,MATCH('table (2)'!$L17,m!$A$2:$A$50,0),MATCH('table (2)'!Q$4,m!$B$1:$AX$1,0)) -> 11.715064 | R17: =INDEX(m!$B$2:$AX$50,MATCH('table (2)'!$L17,m!$A$2:$A$50,0),MATCH('table (2)'!R$4,m!$B$1:$AX$1,0)) -> 12 | S17: =INDEX(m!$B$2:$AZ$50,MATCH('table (2)'!$L17,m!$A$2:$A$50,0),MATCH('table (2)'!S$4,m!$B$1:$AZ$1,0)) -> 12 | U17: 11.715064 | V17: 12 | W17: 12
B18: Хадгаламжийн хүү | C18: %, шинэ, хуг-тай, банк | D18: =M18 -> 6.2153547 | E18: =N18 -> 11.083484 | F18: =O18 -> 11.789334 | G18: =P18 -> 12.1318 | H18: =Q18 -> 11.79411 | I18: =R18 -> 12.154919 | J18: =S18 -> 12.205959 | L18: rate_timedepo_mnt_new | M18: =INDEX(m!$B$2:$AX$50,MATCH('table (2)'!$L18,m!$A$2:$A$50,0),MATCH('table (2)'!M$4,m!$B$1:$AX$1,0)) -> 6.2153547 | N18: =INDEX(m!$B$2:$AX$50,MATCH('table (2)'!$L18,m!$A$2:$A$50,0),MATCH('table (2)'!N$4,m!$B$1:$AX$1,0)) -> 11.083484 | O18: =INDEX(m!$B$2:$AX$50,MATCH('table (2)'!$L18,m!$A$2:$A$50,0),MATCH('table (2)'!O$4,m!$B$1:$AX$1,0)) -> 11.789334 | P18: =INDEX(m!$B$2:$AX$50,MATCH('table (2)'!$L18,m!$A$2:$A$50,0),MATCH('table (2)'!P$4,m!$B$1:$AX$1,0)) -> 12.1318 | Q18: =INDEX(m!$B$2:$AX$50,MATCH('table (2)'!$L18,m!$A$2:$A$50,0),MATCH('table (2)'!Q$4,m!$B$1:$AX$1,0)) -> 11.79411 | R18: =INDEX(m!$B$2:$AX$50,MATCH('table (2)'!$L18,m!$A$2:$A$50,0),MATCH('table (2)'!R$4,m!$B$1:$AX$1,0)) -> 12.154919 | S18: =INDEX(m!$B$2:$AZ$50,MATCH('table (2)'!$L18,m!$A$2:$A$50,0),MATCH('table (2)'!S$4,m!$B$1:$AZ$1,0)) -> 12.205959 | U18: 16.953088 | V18: 17.27256 | W18: 17.09868
B19: Зээлийн хүү | C19: %, шинэ, банк | D19: =M19 -> 14.286499 | E19: =N19 -> 15.715657 | F19: =O19 -> 16.738576 | G19: =P19 -> 16.912679 | H19: =Q19 -> 16.953088 | I19: =R19 -> 17.27256 | J19: =S19 -> 17.260008 | L19: rate_loan_mnt_new | M19: =INDEX(m!$B$2:$AX$50,MATCH('table (2)'!$L19,m!$A$2:$A$50,0),MATCH('table (2)'!M$4,m!$B$1:$AX$1,0)) -> 14.286499 | N19: =INDEX(m!$B$2:$AX$50,MATCH('table (2)'!$L19,m!$A$2:$A$50,0),MATCH('table (2)'!N$4,m!$B$1:$AX$1,0)) -> 15.715657 | O19: =INDEX(m!$B$2:$AX$50,MATCH('table (2)'!$L19,m!$A$2:$A$50,0),MATCH('table (2)'!O$4,m!$B$1:$AX$1,0)) -> 16.738576 | P19: =INDEX(m!$B$2:$AX$50,MATCH('table (2)'!$L19,m!$A$2:$A$50,0),MATCH('table (2)'!P$4,m!$B$1:$AX$1,0)) -> 16.912679 | Q19: =INDEX(m!$B$2:$AX$50,MATCH('table (2)'!$L19,m!$A$2:$A$50,0),MATCH('table (2)'!Q$4,m!$B$1:$AX$1,0)) -> 16.953088 | R19: =INDEX(m!$B$2:$AX$50,MATCH('table (2)'!$L19,m!$A$2:$A$50,0),MATCH('table (2)'!R$4,m!$B$1:$AX$1,0)) -> 17.27256 | S19: =INDEX(m!$B$2:$AZ$50,MATCH('table (2)'!$L19,m!$A$2:$A$50,0),MATCH('table (2)'!S$4,m!$B$1:$AZ$1,0)) -> 17.260008 | U19: 11.79411 | V19: 12.154919 | W19: 11.664904
B20: Мөнгөний нийлүүлэлт | C20: %, жилийн (YoY) | D20: =M20 -> 13.817915 | E20: =N20 -> 6.4648482 | F20: =O20 -> 26.830692 | G20: =P20 -> 15.176127 | H20: =Q20 -> 10.917553 | I20: =R20 -> 3.694507 | J20: =S20 -> 5.5599996 | L20: ms_m2_yoy | M20: =INDEX(m!$B$2:$AX$50,MATCH('table (2)'!$L20,m!$A$2:$A$50,0),MATCH('table (2)'!M$4,m!$B$1:$AX$1,0)) -> 13.817915 | N20: =INDEX(m!$B$2:$AX$50,MATCH('table (2)'!$L20,m!$A$2:$A$50,0),MATCH('table (2)'!N$4,m!$B$1:$AX$1,0)) -> 6.4648482 | O20: =INDEX(m!$B$2:$AX$50,MATCH('table (2)'!$L20,m!$A$2:$A$50,0),MATCH('table (2)'!O$4,m!$B$1:$AX$1,0)) -> 26.830692 | P20: =INDEX(m!$B$2:$AX$50,MATCH('table (2)'!$L20,m!$A$2:$A$50,0),MATCH('table (2)'!P$4,m!$B$1:$AX$1,0)) -> 15.176127 | Q20: =INDEX(m!$B$2:$AX$50,MATCH('table (2)'!$L20,m!$A$2:$A$50,0),MATCH('table (2)'!Q$4,m!$B$1:$AX$1,0)) -> 10.917553 | R20: =INDEX(m!$B$2:$AX$50,MATCH('table (2)'!$L20,m!$A$2:$A$50,0),MATCH('table (2)'!R$4,m!$B$1:$AX$1,0)) -> 3.694507 | S20: =INDEX(m!$B$2:$AZ$50,MATCH('table (2)'!$L20,m!$A$2:$A$50,0),MATCH('table (2)'!S$4,m!$B$1:$AZ$1,0)) -> 5.5599996 | U20: 10.917553 | V20: 3.694507 | W20: 3.1831038
C21: %, улирлын (QoQ) | I21: =R21 -> 14.61722 | J21: =S21 -> 10.489942 | L21: ms_m2_qoq | M21: =INDEX(m!$B$2:$AX$50,MATCH('table (2)'!$L21,m!$A$2:$A$50,0),MATCH('table (2)'!M$4,m!$B$1:$AX$1,0)) -> 8.8922852 | N21: =INDEX(m!$B$2:$AX$50,MATCH('table (2)'!$L21,m!$A$2:$A$50,0),MATCH('table (2)'!N$4,m!$B$1:$AX$1,0)) -> 32.068315 | O21: =INDEX(m!$B$2:$AX$50,MATCH('table (2)'!$L21,m!$A$2:$A$50,0),MATCH('table (2)'!O$4,m!$B$1:$AX$1,0)) -> 53.155141 | P21: =INDEX(m!$B$2:$AX$50,MATCH('table (2)'!$L21,m!$A$2:$A$50,0),MATCH('table (2)'!P$4,m!$B$1:$AX$1,0)) -> 14.651926 | Q21: =INDEX(m!$B$2:$AX$50,MATCH('table (2)'!$L21,m!$A$2:$A$50,0),MATCH('table (2)'!Q$4,m!$B$1:$AX$1,0)) -> -17.081982 | R21: =INDEX(m!$B$2:$AX$50,MATCH('table (2)'!$L21,m!$A$2:$A$50,0),MATCH('table (2)'!R$4,m!$B$1:$AX$1,0)) -> 14.61722 | S21: =INDEX(m!$B$2:$AZ$50,MATCH('table (2)'!$L21,m!$A$2:$A$50,0),MATCH('table (2)'!S$4,m!$B$1:$AZ$1,0)) -> 10.489942 | U21: -4.2704954 | V21: 3.6543051 | W21: 3.7934651
C22: %, сарын (MoM) | H22: =Q22 -> -0.84348043 | I22: =R22 -> 3.4888374 | J22: =S22 -> -0.35854949 | L22: ms_m2_mom | M22: =INDEX(m!$B$2:$AX$50,MATCH('table (2)'!$L22,m!$A$2:$A$50,0),MATCH('table (2)'!M$4,m!$B$1:$AX$1,0)) -> 2.2465119 | N22: =INDEX(m!$B$2:$AX$50,MATCH('table (2)'!$L22,m!$A$2:$A$50,0),MATCH('table (2)'!N$4,m!$B$1:$AX$1,0)) -> 8.4947561 | O22: =INDEX(m!$B$2:$AX$50,MATCH('table (2)'!$L22,m!$A$2:$A$50,0),MATCH('table (2)'!O$4,m!$B$1:$AX$1,0)) -> 6.2742625 | P22: =INDEX(m!$B$2:$AX$50,MATCH('table (2)'!$L22,m!$A$2:$A$50,0),MATCH('table (2)'!P$4,m!$B$1:$AX$1,0)) -> 4.4037276 | Q22: =INDEX(m!$B$2:$AX$50,MATCH('table (2)'!$L22,m!$A$2:$A$50,0),MATCH('table (2)'!Q$4,m!$B$1:$AX$1,0)) -> -0.84348043 | R22: =INDEX(m!$B$2:$AX$50,MATCH('table (2)'!$L22,m!$A$2:$A$50,0),MATCH('table (2)'!R$4,m!$B$1:$AX$1,0)) -> 3.4888374 | S22: =INDEX(m!$B$2:$AZ$50,MATCH('table (2)'!$L22,m!$A$2:$A$50,0),MATCH('table (2)'!S$4,m!$B$1:$AZ$1,0)) -> -0.35854949 | U22: -0.84348043 | V22: 3.4888374 | W22: 0.19593758
C23: Дүн, их наяд төг. | D23: =M23 -> 27.863477 | E23: =N23 -> 29.664808 | F23: =O23 -> 37.624081 | G23: =P23 -> 43.33396 | H23: =Q23 -> 41.483385 | I23: =R23 -> 42.999314 | J23: =S23 -> 44.126965 | L23: ms_m2 | M23: =INDEX(m!$B$2:$AX$50,MATCH('table (2)'!$L23,m!$A$2:$A$50,0),MATCH('table (2)'!M$4,m!$B$1:$AX$1,0)) -> 27.863477 | N23: =INDEX(m!$B$2:$AX$50,MATCH('table (2)'!$L23,m!$A$2:$A$50,0),MATCH('table (2)'!N$4,m!$B$1:$AX$1,0)) -> 29.664808 | O23: =INDEX(m!$B$2:$AX$50,MATCH('table (2)'!$L23,m!$A$2:$A$50,0),MATCH('table (2)'!O$4,m!$B$1:$AX$1,0)) -> 37.624081 | P23: =INDEX(m!$B$2:$AX$50,MATCH('table (2)'!$L23,m!$A$2:$A$50,0),MATCH('table (2)'!P$4,m!$B$1:$AX$1,0)) -> 43.33396 | Q23: =INDEX(m!$B$2:$AX$50,MATCH('table (2)'!$L23,m!$A$2:$A$50,0),MATCH('table (2)'!Q$4,m!$B$1:$AX$1,0)) -> 41.483385 | R23: =INDEX(m!$B$2:$AX$50,MATCH('table (2)'!$L23,m!$A$2:$A$50,0),MATCH('table (2)'!R$4,m!$B$1:$AX$1,0)) -> 42.999314 | S23: =INDEX(m!$B$2:$AZ$50,MATCH('table (2)'!$L23,m!$A$2:$A$50,0),MATCH('table (2)'!S$4,m!$B$1:$AZ$1,0)) -> 44.126965 | U23: 41.483385 | V23: 42.999314 | W23: 43.083566
C24: %, ДНБ харьцах | D24: =M24 -> 63.972372 | E24: =N24 -> 55.086272 | F24: =O24 -> 53.4118 | G24: =P24 -> 53.722193 | H24: =Q24 -> 50.887918 | I24: =R24 -> 52.747518 | J24: =J23/J66*100 -> 54.130814 | L24: m2_gdp | M24: =INDEX(m!$B$2:$AX$50,MATCH('table (2)'!$L24,m!$A$2:$A$50,0),MATCH('table (2)'!M$4,m!$B$1:$AX$1,0)) -> 63.972372 | N24: =INDEX(m!$B$2:$AX$50,MATCH('table (2)'!$L24,m!$A$2:$A$50,0),MATCH('table (2)'!N$4,m!$B$1:$AX$1,0)) -> 55.086272 | O24: =INDEX(m!$B$2:$AX$50,MATCH('table (2)'!$L24,m!$A$2:$A$50,0),MATCH('table (2)'!O$4,m!$B$1:$AX$1,0)) -> 53.4118 | P24: =INDEX(m!$B$2:$AX$50,MATCH('table (2)'!$L24,m!$A$2:$A$50,0),MATCH('table (2)'!P$4,m!$B$1:$AX$1,0)) -> 53.722193 | Q24: =INDEX(m!$B$2:$AX$50,MATCH('table (2)'!$L24,m!$A$2:$A$50,0),MATCH('table (2)'!Q$4,m!$B$1:$AX$1,0)) -> 50.887918 | R24: =R23/($H$23/$H$24) -> 52.747518 | S24: =S23/($H$23/$H$24) -> 54.130814 | U24: 50.307353
B25: Банкны зээл | C25: %, жилийн (YoY) | D25: =M25 -> 21.856801 | E25: =N25 -> 8.326797 | F25: =O25 -> 21.879296 | G25: =P25 -> 34.61869 | H25: =Q25 -> 32.779266 | I25: =R25 -> 27.109139 | J25: =S25 -> 22.760333 | L25: bank_ass_credit_nfi_yoy | M25: =INDEX(m!$B$2:$AX$50,MATCH('table (2)'!$L25,m!$A$2:$A$50,0),MATCH('table (2)'!M$4,m!$B$1:$AX$1,0)) -> 21.856801 | N25: =INDEX(m!$B$2:$AX$50,MATCH('table (2)'!$L25,m!$A$2:$A$50,0),MATCH('table (2)'!N$4,m!$B$1:$AX$1,0)) -> 8.326797 | O25: =INDEX(m!$B$2:$AX$50,MATCH('table (2)'!$L25,m!$A$2:$A$50,0),MATCH('table (2)'!O$4,m!$B$1:$AX$1,0)) -> 21.879296 | P25: =INDEX(m!$B$2:$AX$50,MATCH('table (2)'!$L25,m!$A$2:$A$50,0),MATCH('table (2)'!P$4,m!$B$1:$AX$1,0)) -> 34.61869 | Q25: =INDEX(m!$B$2:$AX$50,MATCH('table (2)'!$L25,m!$A$2:$A$50,0),MATCH('table (2)'!Q$4,m!$B$1:$AX$1,0)) -> 32.779266 | R25: =INDEX(m!$B$2:$AX$50,MATCH('table (2)'!$L25,m!$A$2:$A$50,0),MATCH('table (2)'!R$4,m!$B$1:$AX$1,0)) -> 27.109139 | S25: =INDEX(m!$B$2:$AZ$50,MATCH('table (2)'!$L25,m!$A$2:$A$50,0),MATCH('table (2)'!S$4,m!$B$1:$AZ$1,0)) -> 22.760333 | U25: 32.779266 | V25: 27.109139 | W25: 27.384671 | AD25: =H23/H24*100 -> 81.519123
C26: %, улирлын (QoQ) | I26: =R26 -> 39.591237 | J26: =S26 -> 5.8031325 | L26: bank_ass_credit_nfi_qoq | M26: =INDEX(m!$B$2:$AX$50,MATCH('table (2)'!$L26,m!$A$2:$A$50,0),MATCH('table (2)'!M$4,m!$B$1:$AX$1,0)) -> 13.679303 | N26: =INDEX(m!$B$2:$AX$50,MATCH('table (2)'!$L26,m!$A$2:$A$50,0),MATCH('table (2)'!N$4,m!$B$1:$AX$1,0)) -> -6.8829885 | O26: =INDEX(m!$B$2:$AX$50,MATCH('table (2)'!$L26,m!$A$2:$A$50,0),MATCH('table (2)'!O$4,m!$B$1:$AX$1,0)) -> 19.694894 | P26: =INDEX(m!$B$2:$AX$50,MATCH('table (2)'!$L26,m!$A$2:$A$50,0),MATCH('table (2)'!P$4,m!$B$1:$AX$1,0)) -> 19.721123 | Q26: =INDEX(m!$B$2:$AX$50,MATCH('table (2)'!$L26,m!$A$2:$A$50,0),MATCH('table (2)'!Q$4,m!$B$1:$AX$1,0)) -> 19.732671 | R26: =INDEX(m!$B$2:$AX$50,MATCH('table (2)'!$L26,m!$A$2:$A$50,0),MATCH('table (2)'!R$4,m!$B$1:$AX$1,0)) -> 39.591237 | S26: =INDEX(m!$B$2:$AZ$50,MATCH('table (2)'!$L26,m!$A$2:$A$50,0),MATCH('table (2)'!S$4,m!$B$1:$AZ$1,0)) -> 5.8031325 | U26: 4.9331678 | V26: 9.8978094 | W26: 7.6359818
C27: %, сарын (MoM) | H27: =Q27 -> 0.33498532 | I27: =R27 -> 4.7995553 | J27: =S27 -> 1.1143131 | L27: bank_ass_credit_nfi_mom | M27: =INDEX(m!$B$2:$AX$50,MATCH('table (2)'!$L27,m!$A$2:$A$50,0),MATCH('table (2)'!M$4,m!$B$1:$AX$1,0)) -> 3.0664379 | N27: =INDEX(m!$B$2:$AX$50,MATCH('table (2)'!$L27,m!$A$2:$A$50,0),MATCH('table (2)'!N$4,m!$B$1:$AX$1,0)) -> -0.41185332 | O27: =INDEX(m!$B$2:$AX$50,MATCH('table (2)'!$L27,m!$A$2:$A$50,0),MATCH('table (2)'!O$4,m!$B$1:$AX$1,0)) -> 1.8434083 | P27: =INDEX(m!$B$2:$AX$50,MATCH('table (2)'!$L27,m!$A$2:$A$50,0),MATCH('table (2)'!P$4,m!$B$1:$AX$1,0)) -> 2.6773363 | Q27: =INDEX(m!$B$2:$AX$50,MATCH('table (2)'!$L27,m!$A$2:$A$50,0),MATCH('table (2)'!Q$4,m!$B$1:$AX$1,0)) -> 0.33498532 | R27: =INDEX(m!$B$2:$AX$50,MATCH('table (2)'!$L27,m!$A$2:$A$50,0),MATCH('table (2)'!R$4,m!$B$1:$AX$1,0)) -> 4.7995553 | S27: =INDEX(m!$B$2:$AZ$50,MATCH('table (2)'!$L27,m!$A$2:$A$50,0),MATCH('table (2)'!S$4,m!$B$1:$AZ$1,0)) -> 1.1143131 | U27: 0.33498532 | V27: 4.7995553 | W27: 0.41679942
C28: Дүн, их наяд төг. | L28: bank_ass_credit_nfi | AD28: =H29*$AD$25/100 -> 3.7668662e-05 | AE28: =AD28*(1+I27/100) -> 3.9476591e-05 | AF28: =AE28*(1+#REF!/100) -> #REF!
C29: %, ДНБ харьцах | D29: =M29 -> 4.6371737e-05 | E29: =N29 -> 4.0628796e-05 | F29: =O29 -> 3.7855881e-05 | G29: =P29 -> 4.4503357e-05 | H29: =Q29 -> 4.6208375e-05 | I29: =R29 -> 4.93292e-05 | J29: =S29 -> 4.9201557e-05 | L29: loan_gdp | M29: =INDEX(m!$B$2:$AX$50,MATCH('table (2)'!$L29,m!$A$2:$A$50,0),MATCH('table (2)'!M$4,m!$B$1:$AX$1,0)) -> 4.6371737e-05 | N29: =INDEX(m!$B$2:$AX$50,MATCH('table (2)'!$L29,m!$A$2:$A$50,0),MATCH('table (2)'!N$4,m!$B$1:$AX$1,0)) -> 4.0628796e-05 | O29: =INDEX(m!$B$2:$AX$50,MATCH('table (2)'!$L29,m!$A$2:$A$50,0),MATCH('table (2)'!O$4,m!$B$1:$AX$1,0)) -> 3.7855881e-05 | P29: =INDEX(m!$B$2:$AX$50,MATCH('table (2)'!$L29,m!$A$2:$A$50,0),MATCH('table (2)'!P$4,m!$B$1:$AX$1,0)) -> 4.4503357e-05 | Q29: =INDEX(m!$B$2:$AX$50,MATCH('table (2)'!$L29,m!$A$2:$A$50,0),MATCH('table (2)'!Q$4,m!$B$1:$AX$1,0)) -> 4.6208375e-05 | R29: =INDEX(m!$B$2:$AX$50,MATCH('table (2)'!$L29,m!$A$2:$A$50,0),MATCH('table (2)'!R$4,m!$B$1:$AX$1,0)) -> 4.93292e-05 | S29: =INDEX(m!$B$2:$AZ$50,MATCH('table (2)'!$L29,m!$A$2:$A$50,0),MATCH('table (2)'!S$4,m!$B$1:$AZ$1,0)) -> 4.9201557e-05 | U29: 45.681198 | AE29: =AE28/$AD$25*100 -> 4.8426172e-05 | AF29: =AF28/$AD$25*100 -> #REF!
B30: Банкны зээл /иргэд/ | C30: %, жилийн (YoY) | D30: =M30 -> 21.788529 | E30: =N30 -> 11.139411 | F30: =O30 -> 32.454539 | G30: =P30 -> 42.418936 | H30: =Q30 -> 36.083349 | I30: =R30 -> 26.618682 | J30: =S30 -> 21.313132 | L30: dc_loan_ind_yoy | M30: =INDEX(m!$B$2:$AX$50,MATCH('table (2)'!$L30,m!$A$2:$A$50,0),MATCH('table (2)'!M$4,m!$B$1:$AX$1,0)) -> 21.788529 | N30: =INDEX(m!$B$2:$AX$50,MATCH('table (2)'!$L30,m!$A$2:$A$50,0),MATCH('table (2)'!N$4,m!$B$1:$AX$1,0)) -> 11.139411 | O30: =INDEX(m!$B$2:$AX$50,MATCH('table (2)'!$L30,m!$A$2:$A$50,0),MATCH('table (2)'!O$4,m!$B$1:$AX$1,0)) -> 32.454539 | P30: =INDEX(m!$B$2:$AX$50,MATCH('table (2)'!$L30,m!$A$2:$A$50,0),MATCH('table (2)'!P$4,m!$B$1:$AX$1,0)) -> 42.418936 | Q30: =INDEX(m!$B$2:$AX$50,MATCH('table (2)'!$L30,m!$A$2:$A$50,0),MATCH('table (2)'!Q$4,m!$B$1:$AX$1,0)) -> 36.083349 | R30: =INDEX(m!$B$2:$AX$50,MATCH('table (2)'!$L30,m!$A$2:$A$50,0),MATCH('table (2)'!R$4,m!$B$1:$AX$1,0)) -> 26.618682 | S30: =INDEX(m!$B$2:$AZ$50,MATCH('table (2)'!$L30,m!$A$2:$A$50,0),MATCH('table (2)'!S$4,m!$B$1:$AZ$1,0)) -> 21.313132 | U30: 36.083349 | V30: 26.618682 | W30: 27.245572
C31: %, улирлын (QoQ) | I31: =R31 -> 26.658868 | J31: =S31 -> 11.930864 | L31: dc_loan_ind_qoq | M31: =INDEX(m!$B$2:$AX$50,MATCH('table (2)'!$L31,m!$A$2:$A$50,0),MATCH('table (2)'!M$4,m!$B$1:$AX$1,0)) -> 13.246441 | N31: =INDEX(m!$B$2:$AX$50,MATCH('table (2)'!$L31,m!$A$2:$A$50,0),MATCH('table (2)'!N$4,m!$B$1:$AX$1,0)) -> -1.0319146 | O31: =INDEX(m!$B$2:$AX$50,MATCH('table (2)'!$L31,m!$A$2:$A$50,0),MATCH('table (2)'!O$4,m!$B$1:$AX$1,0)) -> 19.474927 | P31: =INDEX(m!$B$2:$AX$50,MATCH('table (2)'!$L31,m!$A$2:$A$50,0),MATCH('table (2)'!P$4,m!$B$1:$AX$1,0)) -> 20.262524 | Q31: =INDEX(m!$B$2:$AX$50,MATCH('table (2)'!$L31,m!$A$2:$A$50,0),MATCH('table (2)'!Q$4,m!$B$1:$AX$1,0)) -> 20.457406 | R31: =INDEX(m!$B$2:$AX$50,MATCH('table (2)'!$L31,m!$A$2:$A$50,0),MATCH('table (2)'!R$4,m!$B$1:$AX$1,0)) -> 26.658868 | S31: =INDEX(m!$B$2:$AZ$50,MATCH('table (2)'!$L31,m!$A$2:$A$50,0),MATCH('table (2)'!S$4,m!$B$1:$AZ$1,0)) -> 11.930864 | U31: 5.1143516 | V31: 6.6647171 | W31: 6.030327
C32: %, сарын (MoM) | H32: =Q32 -> -1.4799656 | I32: =R32 -> 2.2924228 | J32: =S32 -> 1.4820993 | L32: dc_loan_ind_mom | M32: =INDEX(m!$B$2:$AX$50,MATCH('table (2)'!$L32,m!$A$2:$A$50,0),MATCH('table (2)'!M$4,m!$B$1:$AX$1,0)) -> 1.6270711 | N32: =INDEX(m!$B$2:$AX$50,MATCH('table (2)'!$L32,m!$A$2:$A$50,0),MATCH('table (2)'!N$4,m!$B$1:$AX$1,0)) -> 0.28002941 | O32: =INDEX(m!$B$2:$AX$50,MATCH('table (2)'!$L32,m!$A$2:$A$50,0),MATCH('table (2)'!O$4,m!$B$1:$AX$1,0)) -> 0.31258369 | P32: =INDEX(m!$B$2:$AX$50,MATCH('table (2)'!$L32,m!$A$2:$A$50,0),MATCH('table (2)'!P$4,m!$B$1:$AX$1,0)) -> 1.7771209 | Q32: =INDEX(m!$B$2:$AX$50,MATCH('table (2)'!$L32,m!$A$2:$A$50,0),MATCH('table (2)'!Q$4,m!$B$1:$AX$1,0)) -> -1.4799656 | R32: =INDEX(m!$B$2:$AX$50,MATCH('table (2)'!$L32,m!$A$2:$A$50,0),MATCH('table (2)'!R$4,m!$B$1:$AX$1,0)) -> 2.2924228 | S32: =INDEX(m!$B$2:$AZ$50,MATCH('table (2)'!$L32,m!$A$2:$A$50,0),MATCH('table (2)'!S$4,m!$B$1:$AZ$1,0)) -> 1.4820993 | U32: -1.4799656 | V32: 2.2924228 | W32: 1.8448914 | AD32: =H34*$AD$25/100 -> 2.3361404e-05
C33: Дүн, их наяд төг. | L33: dc_loan_ind
C34: %, ДНБ харьцах | D34: =M34 -> 2.4338365e-05 | E34: =N34 -> 2.1877827e-05 | F34: =O34 -> 2.2153405e-05 | G34: =P34 -> 2.755258e-05 | H34: =Q34 -> 2.8657575e-05 | I34: =R34 -> 2.9693033e-05 | J34: =I34*(1+J32/100) -> 3.0133113e-05 | L34: loan_ind_gdp | M34: =INDEX(m!$B$2:$AX$50,MATCH('table (2)'!$L34,m!$A$2:$A$50,0),MATCH('table (2)'!M$4,m!$B$1:$AX$1,0)) -> 2.4338365e-05 | N34: =INDEX(m!$B$2:$AX$50,MATCH('table (2)'!$L34,m!$A$2:$A$50,0),MATCH('table (2)'!N$4,m!$B$1:$AX$1,0)) -> 2.1877827e-05 | O34: =INDEX(m!$B$2:$AX$50,MATCH('table (2)'!$L34,m!$A$2:$A$50,0),MATCH('table (2)'!O$4,m!$B$1:$AX$1,0)) -> 2.2153405e-05 | P34: =INDEX(m!$B$2:$AX$50,MATCH('table (2)'!$L34,m!$A$2:$A$50,0),MATCH('table (2)'!P$4,m!$B$1:$AX$1,0)) -> 2.755258e-05 | Q34: =INDEX(m!$B$2:$AX$50,MATCH('table (2)'!$L34,m!$A$2:$A$50,0),MATCH('table (2)'!Q$4,m!$B$1:$AX$1,0)) -> 2.8657575e-05 | R34: =INDEX(m!$B$2:$AX$50,MATCH('table (2)'!$L34,m!$A$2:$A$50,0),MATCH('table (2)'!R$4,m!$B$1:$AX$1,0)) -> 2.9693033e-05 | S34: =INDEX(m!$B$2:$AZ$50,MATCH('table (2)'!$L34,m!$A$2:$A$50,0),MATCH('table (2)'!S$4,m!$B$1:$AZ$1,0)) -> 3.0063412e-05 | U34: 28.330629
B35: Банкны зээл /ААН/ | C35: %, жилийн (YoY) | D35: =M35 -> 23.628687 | E35: =N35 -> 2.93599 | F35: =O35 -> 13.039963 | G35: =P35 -> 20.052926 | H35: =Q35 -> 24.624443 | I35: =R35 -> 25.506298 | J35: =S35 -> 23.89305 | L35: dc_loan_corp_yoy | M35: =INDEX(m!$B$2:$AX$50,MATCH('table (2)'!$L35,m!$A$2:$A$50,0),MATCH('table (2)'!M$4,m!$B$1:$AX$1,0)) -> 23.628687 | N35: =INDEX(m!$B$2:$AX$50,MATCH('table (2)'!$L35,m!$A$2:$A$50,0),MATCH('table (2)'!N$4,m!$B$1:$AX$1,0)) -> 2.93599 | O35: =INDEX(m!$B$2:$AX$50,MATCH('table (2)'!$L35,m!$A$2:$A$50,0),MATCH('table (2)'!O$4,m!$B$1:$AX$1,0)) -> 13.039963 | P35: =INDEX(m!$B$2:$AX$50,MATCH('table (2)'!$L35,m!$A$2:$A$50,0),MATCH('table (2)'!P$4,m!$B$1:$AX$1,0)) -> 20.052926 | Q35: =INDEX(m!$B$2:$AX$50,MATCH('table (2)'!$L35,m!$A$2:$A$50,0),MATCH('table (2)'!Q$4,m!$B$1:$AX$1,0)) -> 24.624443 | R35: =INDEX(m!$B$2:$AX$50,MATCH('table (2)'!$L35,m!$A$2:$A$50,0),MATCH('table (2)'!R$4,m!$B$1:$AX$1,0)) -> 25.506298 | S35: =INDEX(m!$B$2:$AZ$50,MATCH('table (2)'!$L35,m!$A$2:$A$50,0),MATCH('table (2)'!S$4,m!$B$1:$AZ$1,0)) -> 23.89305 | U35: 24.624443 | V35: 25.506298 | W35: 25.175621 | AD35: =H37*$AD$25/100 -> 0 | AE35: =AD35*(1+I36/100) -> 0 | AF35: =AE35*(1+#REF!/100) -> #REF!
C36: %, улирлын (QoQ) | I36: =R36 -> 60.640284 | J36: =S36 -> 0.46769691 | L36: dc_loan_corp_qoq | M36: =INDEX(m!$B$2:$AX$50,MATCH('table (2)'!$L36,m!$A$2:$A$50,0),MATCH('table (2)'!M$4,m!$B$1:$AX$1,0)) -> 19.911705 | N36: =INDEX(m!$B$2:$AX$50,MATCH('table (2)'!$L36,m!$A$2:$A$50,0),MATCH('table (2)'!N$4,m!$B$1:$AX$1,0)) -> -26.585109 | O36: =INDEX(m!$B$2:$AX$50,MATCH('table (2)'!$L36,m!$A$2:$A$50,0),MATCH('table (2)'!O$4,m!$B$1:$AX$1,0)) -> 20.451713 | P36: =INDEX(m!$B$2:$AX$50,MATCH('table (2)'!$L36,m!$A$2:$A$50,0),MATCH('table (2)'!P$4,m!$B$1:$AX$1,0)) -> 11.875392 | Q36: =INDEX(m!$B$2:$AX$50,MATCH('table (2)'!$L36,m!$A$2:$A$50,0),MATCH('table (2)'!Q$4,m!$B$1:$AX$1,0)) -> 17.437692 | R36: =INDEX(m!$B$2:$AX$50,MATCH('table (2)'!$L36,m!$A$2:$A$50,0),MATCH('table (2)'!R$4,m!$B$1:$AX$1,0)) -> 60.640284 | S36: =INDEX(m!$B$2:$AZ$50,MATCH('table (2)'!$L36,m!$A$2:$A$50,0),MATCH('table (2)'!S$4,m!$B$1:$AZ$1,0)) -> 0.46769691 | U36: 4.3594229 | V36: 15.160071 | W36: 10.16329 | AD36: =H39*$AD$25/100 -> 1.4364974e-05 | AE36: =AD36*(1+I37/100) -> 1.5582401e-05 | AF36: =AE36*(1+#REF!/100) -> #REF!
C37: %, сарын (MoM) | I37: =R37 -> 8.4749717 | J37: =S37 -> 0.87055907 | L37: dc_loan_corp_mom | M37: =INDEX(m!$B$2:$AX$50,MATCH('table (2)'!$L37,m!$A$2:$A$50,0),MATCH('table (2)'!M$4,m!$B$1:$AX$1,0)) -> 4.1400216 | N37: =INDEX(m!$B$2:$AX$50,MATCH('table (2)'!$L37,m!$A$2:$A$50,0),MATCH('table (2)'!N$4,m!$B$1:$AX$1,0)) -> -4.3054449 | O37: =INDEX(m!$B$2:$AX$50,MATCH('table (2)'!$L37,m!$A$2:$A$50,0),MATCH('table (2)'!O$4,m!$B$1:$AX$1,0)) -> 3.842761 | P37: =INDEX(m!$B$2:$AX$50,MATCH('table (2)'!$L37,m!$A$2:$A$50,0),MATCH('table (2)'!P$4,m!$B$1:$AX$1,0)) -> 2.6325165 | Q37: =INDEX(m!$B$2:$AX$50,MATCH('table (2)'!$L37,m!$A$2:$A$50,0),MATCH('table (2)'!Q$4,m!$B$1:$AX$1,0)) -> 3.6295985 | R37: =INDEX(m!$B$2:$AX$50,MATCH('table (2)'!$L37,m!$A$2:$A$50,0),MATCH('table (2)'!R$4,m!$B$1:$AX$1,0)) -> 8.4749717 | S37: =INDEX(m!$B$2:$AZ$50,MATCH('table (2)'!$L37,m!$A$2:$A$50,0),MATCH('table (2)'!S$4,m!$B$1:$AZ$1,0)) -> 0.87055907 | U37: 3.6295985 | V37: 8.4749717 | W37: -1.5436548 | AE37: =AE36/$AD$25*100 -> 1.9115026e-05 | AF37: =AF36/$AD$25*100 -> #REF!
C38: Дүн, их наяд төг. | L38: dc_loan_corp
C39: %, ДНБ харьцах | D39: =M39 -> 2.2623423e-05 | E39: =N39 -> 1.8835201e-05 | F39: =O39 -> 1.6276901e-05 | G39: =P39 -> 1.7064695e-05 | H39: =Q39 -> 1.76216e-05 | I39: =R39 -> 1.9712495e-05 | J39: =I39*(1+J37/100) -> 1.9884104e-05 | L39: loan_corp_gdp | M39: =INDEX(m!$B$2:$AX$50,MATCH('table (2)'!$L39,m!$A$2:$A$50,0),MATCH('table (2)'!M$4,m!$B$1:$AX$1,0)) -> 2.2623423e-05 | N39: =INDEX(m!$B$2:$AX$50,MATCH('table (2)'!$L39,m!$A$2:$A$50,0),MATCH('table (2)'!N$4,m!$B$1:$AX$1,0)) -> 1.8835201e-05 | O39: =INDEX(m!$B$2:$AX$50,MATCH('table (2)'!$L39,m!$A$2:$A$50,0),MATCH('table (2)'!O$4,m!$B$1:$AX$1,0)) -> 1.6276901e-05 | P39: =INDEX(m!$B$2:$AX$50,MATCH('table (2)'!$L39,m!$A$2:$A$50,0),MATCH('table (2)'!P$4,m!$B$1:$AX$1,0)) -> 1.7064695e-05 | Q39: =INDEX(m!$B$2:$AX$50,MATCH('table (2)'!$L39,m!$A$2:$A$50,0),MATCH('table (2)'!Q$4,m!$B$1:$AX$1,0)) -> 1.76216e-05 | R39: =INDEX(m!$B$2:$AX$50,MATCH('table (2)'!$L39,m!$A$2:$A$50,0),MATCH('table (2)'!R$4,m!$B$1:$AX$1,0)) -> 1.9712495e-05 | S39: =INDEX(m!$B$2:$AZ$50,MATCH('table (2)'!$L39,m!$A$2:$A$50,0),MATCH('table (2)'!S$4,m!$B$1:$AZ$1,0)) -> 1.9402981e-05 | U39: 17.42056
B40: Эдийн засгийн өсөлт | C40: %, жилийн (YoY) | D40: =M40 -> 1.6367695 | E40: =N40 -> 5.0327097 | F40: =O40 -> 7.4221129 | G40: =P40 -> 5.1220452 | H40: =Q40 -> 2.6420538 | I40: =R40 -> 5.6194993 | J40: =S40 -> 5.9409693 | M40: =INDEX(q!$B$2:$S$5,MATCH("gdp_q4",q!$A$2:$A$5,0),MATCH(M3,q!$B$1:$S$1,0)) -> 1.6367695 | N40: =INDEX(q!$B$2:$S$5,MATCH("gdp_q4",q!$A$2:$A$5,0),MATCH(N3,q!$B$1:$S$1,0)) -> 5.0327097 | O40: =INDEX(q!$B$2:$S$5,MATCH("gdp_q4",q!$A$2:$A$5,0),MATCH(O3,q!$B$1:$S$1,0)) -> 7.4221129 | P40: =INDEX(q!$B$2:$S$5,MATCH("gdp_q4",q!$A$2:$A$5,0),MATCH(P3,q!$B$1:$S$1,0)) -> 5.1220452 | Q40: =INDEX(q!$B$2:$S$5,MATCH("gdp_q1",q!$A$2:$A$5,0),MATCH(Q3,q!$B$1:$S$1,0)) -> 2.6420538 | R40: =INDEX(q!$B$2:$S$5,MATCH("gdp_q2",q!$A$2:$A$5,0),MATCH(R3,q!$B$1:$S$1,0)) -> 5.6194993 | S40: =INDEX(q!$B$2:$S$5,MATCH("gdp_q3",q!$A$2:$A$5,0),MATCH(S3,q!$B$1:$S$1,0)) -> 5.9409693 | U40: -16.174044 | V40: -6.1173514 | W40: -6.0692058
B41: Улсын төсвийн орлого | C41: %, жилийн (YoY) | D41: =M41 -> 37.043534 | E41: =N41 -> 30.430229 | F41: =O41 -> 30.747673 | G41: =P41 -> 29.061961 | H41: =Q41 -> -16.174044 | I41: =R41 -> -6.1173514 | J41: =S41 -> -2.2617329 | L41: gov_rev_cum_yoy | M41: =INDEX(m!$B$2:$AX$50,MATCH('table (2)'!$L41,m!$A$2:$A$50,0),MATCH('table (2)'!M$4,m!$B$1:$AX$1,0)) -> 37.043534 | N41: =INDEX(m!$B$2:$AX$50,MATCH('table (2)'!$L41,m!$A$2:$A$50,0),MATCH('table (2)'!N$4,m!$B$1:$AX$1,0)) -> 30.430229 | O41: =INDEX(m!$B$2:$AX$50,MATCH('table (2)'!$L41,m!$A$2:$A$50,0),MATCH('table (2)'!O$4,m!$B$1:$AX$1,0)) -> 30.747673 | P41: =INDEX(m!$B$2:$AX$50,MATCH('table (2)'!$L41,m!$A$2:$A$50,0),MATCH('table (2)'!P$4,m!$B$1:$AX$1,0)) -> 29.061961 | Q41: =INDEX(m!$B$2:$AX$50,MATCH('table (2)'!$L41,m!$A$2:$A$50,0),MATCH('table (2)'!Q$4,m!$B$1:$AX$1,0)) -> -16.174044 | R41: =INDEX(m!$B$2:$AX$50,MATCH('table (2)'!$L41,m!$A$2:$A$50,0),MATCH('table (2)'!R$4,m!$B$1:$AX$1,0)) -> -6.1173514 | S41: =INDEX(m!$B$2:$AZ$50,MATCH('table (2)'!$L41,m!$A$2:$A$50,0),MATCH('table (2)'!S$4,m!$B$1:$AZ$1,0)) -> -2.2617329 | U41: 6.4322552 | V41: 14.032792 | W41: 16.578317
C42: Дүн, их наяд төг.** | D42: =M42 -> 14.255235 | E42: =N42 -> 18.593135 | F42: =O42 -> 24.310092 | G42: =P42 -> 31.375081 | H42: =Q42 -> 6.4322552 | I42: =R42 -> 14.032792 | J42: =S42 -> 22.244012 | L42: gov_rev_cum | M42: =INDEX(m!$B$2:$AX$50,MATCH('table (2)'!$L42,m!$A$2:$A$50,0),MATCH('table (2)'!M$4,m!$B$1:$AX$1,0)) -> 14.255235 | N42: =INDEX(m!$B$2:$AX$50,MATCH('table (2)'!$L42,m!$A$2:$A$50,0),MATCH('table (2)'!N$4,m!$B$1:$AX$1,0)) -> 18.593135 | O42: =INDEX(m!$B$2:$AX$50,MATCH('table (2)'!$L42,m!$A$2:$A$50,0),MATCH('table (2)'!O$4,m!$B$1:$AX$1,0)) -> 24.310092 | P42: =INDEX(m!$B$2:$AX$50,MATCH('table (2)'!$L42,m!$A$2:$A$50,0),MATCH('table (2)'!P$4,m!$B$1:$AX$1,0)) -> 31.375081 | Q42: =INDEX(m!$B$2:$AX$50,MATCH('table (2)'!$L42,m!$A$2:$A$50,0),MATCH('table (2)'!Q$4,m!$B$1:$AX$1,0)) -> 6.4322552 | R42: =INDEX(m!$B$2:$AX$50,MATCH('table (2)'!$L42,m!$A$2:$A$50,0),MATCH('table (2)'!R$4,m!$B$1:$AX$1,0)) -> 14.032792 | S42: =INDEX(m!$B$2:$AZ$50,MATCH('table (2)'!$L42,m!$A$2:$A$50,0),MATCH('table (2)'!S$4,m!$B$1:$AZ$1,0)) -> 22.244012 | U42: 7.800466
...

Sheet table
B2: Макро эдийн засгийн хүснэгт - 25Q3
M3: 21Q4 | N3: 22Q4 | O3: 23Q4 | P3: 24Q4 | Q3: 25Q1 | R3: 25Q2 | S3: 25Q3
D4: 21Y | E4: 22Y | F4: 23Y | G4: 24Y | H4: 25Q1 | I4: 25Q2 | J4: 25Q3 | M4: 21M12 | N4: 22M12 | O4: 23M12 | P4: 24M12 | Q4: 25M03 | R4: 25M06 | S4: 25M09 | U4: 25M03 | V4: 25M06 | W4: 25M07
B6: Инфляци | C6: %, жилийн (YoY) | D6: =M6 -> 13.826662 | E6: =N6 -> 13.243298 | F6: =O6 -> 7.9239441 | G6: =P6 -> 8.3598213 | H6: =Q6 -> 9.1020943 | I6: =R6 -> 8.186335 | J6: =S6 -> 9.0299817 | L6: cpi_yoy | M6: =INDEX(m!$B$2:$AY$51,MATCH(table!$L6,m!$A$2:$A$51,0),MATCH(table!M$4,m!$B$1:$AY$1,0)) -> 13.826662 | N6: =INDEX(m!$B$2:$AY$51,MATCH(table!$L6,m!$A$2:$A$51,0),MATCH(table!N$4,m!$B$1:$AY$1,0)) -> 13.243298 | O6: =INDEX(m!$B$2:$AY$51,MATCH(table!$L6,m!$A$2:$A$51,0),MATCH(table!O$4,m!$B$1:$AY$1,0)) -> 7.9239441 | P6: =INDEX(m!$B$2:$AY$51,MATCH(table!$L6,m!$A$2:$A$51,0),MATCH(table!P$4,m!$B$1:$AY$1,0)) -> 8.3598213 | Q6: =INDEX(m!$B$2:$AY$51,MATCH(table!$L6,m!$A$2:$A$51,0),MATCH(table!Q$4,m!$B$1:$AY$1,0)) -> 9.1020943 | R6: =INDEX(m!$B$2:$AY$51,MATCH(table!$L6,m!$A$2:$A$51,0),MATCH(table!R$4,m!$B$1:$AY$1,0)) -> 8.186335 | S6: =INDEX(m!$B$2:$AY$51,MATCH(table!$L6,m!$A$2:$A$51,0),MATCH(table!S$4,m!$B$1:$AY$1,0)) -> 9.0299817 | U6: 9.1020943 | V6: 8.186335 | W6: 8.0997478
C7: %, улирлын (QoQ) | I7: =R7 -> 3.1141627 | J7: =S7 -> 7.0592549 | L7: cpi_qoq | M7: =INDEX(m!$B$2:$AY$51,MATCH(table!$L7,m!$A$2:$A$51,0),MATCH(table!M$4,m!$B$1:$AY$1,0)) -> 15.683225 | N7: =INDEX(m!$B$2:$AY$51,MATCH(table!$L7,m!$A$2:$A$51,0),MATCH(table!N$4,m!$B$1:$AY$1,0)) -> 13.55178 | O7: =INDEX(m!$B$2:$AY$51,MATCH(table!$L7,m!$A$2:$A$51,0),MATCH(table!O$4,m!$B$1:$AY$1,0)) -> 5.5238011 | P7: =INDEX(m!$B$2:$AY$51,MATCH(table!$L7,m!$A$2:$A$51,0),MATCH(table!P$4,m!$B$1:$AY$1,0)) -> 13.263454 | Q7: =INDEX(m!$B$2:$AY$51,MATCH(table!$L7,m!$A$2:$A$51,0),MATCH(table!Q$4,m!$B$1:$AY$1,0)) -> 11.59796 | R7: =INDEX(m!$B$2:$AY$51,MATCH(table!$L7,m!$A$2:$A$51,0),MATCH(table!R$4,m!$B$1:$AY$1,0)) -> 3.1141627 | S7: =INDEX(m!$B$2:$AY$51,MATCH(table!$L7,m!$A$2:$A$51,0),MATCH(table!S$4,m!$B$1:$AY$1,0)) -> 7.0592549 | U7: 2.8994899 | V7: 0.77854068 | W7: 0.39314573
C8: %, улирлын (QoQ @ar) | H8: =Q8 -> 11.59796 | I8: =R8 -> 3.1141627 | J8: =S8 -> 7.0592549 | L8: cpi_qoq | M8: =INDEX(m!$B$2:$AY$51,MATCH(table!$L8,m!$A$2:$A$51,0),MATCH(table!M$4,m!$B$1:$AY$1,0)) -> 15.683225 | N8: =INDEX(m!$B$2:$AY$51,MATCH(table!$L8,m!$A$2:$A$51,0),MATCH(table!N$4,m!$B$1:$AY$1,0)) -> 13.55178 | O8: =INDEX(m!$B$2:$AY$51,MATCH(table!$L8,m!$A$2:$A$51,0),MATCH(table!O$4,m!$B$1:$AY$1,0)) -> 5.5238011 | P8: =INDEX(m!$B$2:$AY$51,MATCH(table!$L8,m!$A$2:$A$51,0),MATCH(table!P$4,m!$B$1:$AY$1,0)) -> 13.263454 | Q8: =INDEX(m!$B$2:$AY$51,MATCH(table!$L8,m!$A$2:$A$51,0),MATCH(table!Q$4,m!$B$1:$AY$1,0)) -> 11.59796 | R8: =INDEX(m!$B$2:$AY$51,MATCH(table!$L8,m!$A$2:$A$51,0),MATCH(table!R$4,m!$B$1:$AY$1,0)) -> 3.1141627 | S8: =INDEX(m!$B$2:$AY$51,MATCH(table!$L8,m!$A$2:$A$51,0),MATCH(table!S$4,m!$B$1:$AY$1,0)) -> 7.0592549 | U8: 0.34988316 | V8: 0.23000865 | W8: -0.050507483
B9: Ам.доллар | D9: =M9 -> 2849.34 | E9: =N9 -> 3444.6 | F9: =O9 -> 3410.69 | G9: =P9 -> 3420.46 | H9: =Q9 -> 3487.61 | I9: =R9 -> 3580.94 | J9: =S9 -> 3594.64 | L9: usd_mnt | M9: =INDEX(m!$B$2:$AY$51,MATCH(table!$L9,m!$A$2:$A$51,0),MATCH(table!M$4,m!$B$1:$AY$1,0)) -> 2849.34 | N9: =INDEX(m!$B$2:$AY$51,MATCH(table!$L9,m!$A$2:$A$51,0),MATCH(table!N$4,m!$B$1:$AY$1,0)) -> 3444.6 | O9: =INDEX(m!$B$2:$AY$51,MATCH(table!$L9,m!$A$2:$A$51,0),MATCH(table!O$4,m!$B$1:$AY$1,0)) -> 3410.69 | P9: =INDEX(m!$B$2:$AY$51,MATCH(table!$L9,m!$A$2:$A$51,0),MATCH(table!P$4,m!$B$1:$AY$1,0)) -> 3420.46 | Q9: =INDEX(m!$B$2:$AY$51,MATCH(table!$L9,m!$A$2:$A$51,0),MATCH(table!Q$4,m!$B$1:$AY$1,0)) -> 3487.61 | R9: =INDEX(m!$B$2:$AY$51,MATCH(table!$L9,m!$A$2:$A$51,0),MATCH(table!R$4,m!$B$1:$AY$1,0)) -> 3580.94 | S9: =INDEX(m!$B$2:$AY$51,MATCH(table!$L9,m!$A$2:$A$51,0),MATCH(table!S$4,m!$B$1:$AY$1,0)) -> 3594.64 | U9: 3487.61 | V9: 3580.94 | W9: 3587.49
C10: %, жилийн (YoY) | D10: =M10 -> -0.01929899 | E10: =N10 -> 20.891154 | F10: =O10 -> -0.98443941 | G10: =P10 -> 0.2864523 | H10: =Q10 -> 3.3062894 | I10: =R10 -> 5.9120687 | J10: =S10 -> 6.3210418 | L10: usd_mnt_yoy | M10: =INDEX(m!$B$2:$AY$51,MATCH(table!$L10,m!$A$2:$A$51,0),MATCH(table!M$4,m!$B$1:$AY$1,0)) -> -0.01929899 | N10: =INDEX(m!$B$2:$AY$51,MATCH(table!$L10,m!$A$2:$A$51,0),MATCH(table!N$4,m!$B$1:$AY$1,0)) -> 20.891154 | O10: =INDEX(m!$B$2:$AY$51,MATCH(table!$L10,m!$A$2:$A$51,0),MATCH(table!O$4,m!$B$1:$AY$1,0)) -> -0.98443941 | P10: =INDEX(m!$B$2:$AY$51,MATCH(table!$L10,m!$A$2:$A$51,0),MATCH(table!P$4,m!$B$1:$AY$1,0)) -> 0.2864523 | Q10: =INDEX(m!$B$2:$AY$51,MATCH(table!$L10,m!$A$2:$A$51,0),MATCH(table!Q$4,m!$B$1:$AY$1,0)) -> 3.3062894 | R10: =INDEX(m!$B$2:$AY$51,MATCH(table!$L10,m!$A$2:$A$51,0),MATCH(table!R$4,m!$B$1:$AY$1,0)) -> 5.9120687 | S10: =INDEX(m!$B$2:$AY$51,MATCH(table!$L10,m!$A$2:$A$51,0),MATCH(table!S$4,m!$B$1:$AY$1,0)) -> 6.3210418 | U10: 3.3062894 | V10: 5.9120687 | W10: 6.1133279
C11: %, улирлын (QoQ) | I11: =R11 -> 10.704179 | J11: =S11 -> 1.5303244 | L11: usd_mnt_qoq | M11: =INDEX(m!$B$2:$AY$51,MATCH(table!$L11,m!$A$2:$A$51,0),MATCH(table!M$4,m!$B$1:$AY$1,0)) -> 0.01965464 | N11: =INDEX(m!$B$2:$AY$51,MATCH(table!$L11,m!$A$2:$A$51,0),MATCH(table!N$4,m!$B$1:$AY$1,0)) -> 13.390859 | O11: =INDEX(m!$B$2:$AY$51,MATCH(table!$L11,m!$A$2:$A$51,0),MATCH(table!O$4,m!$B$1:$AY$1,0)) -> -5.6435901 | P11: =INDEX(m!$B$2:$AY$51,MATCH(table!$L11,m!$A$2:$A$51,0),MATCH(table!P$4,m!$B$1:$AY$1,0)) -> 4.6768197 | Q11: =INDEX(m!$B$2:$AY$51,MATCH(table!$L11,m!$A$2:$A$51,0),MATCH(table!Q$4,m!$B$1:$AY$1,0)) -> 7.852745 | R11: =INDEX(m!$B$2:$AY$51,MATCH(table!$L11,m!$A$2:$A$51,0),MATCH(table!R$4,m!$B$1:$AY$1,0)) -> 10.704179 | S11: =INDEX(m!$B$2:$AY$51,MATCH(table!$L11,m!$A$2:$A$51,0),MATCH(table!S$4,m!$B$1:$AY$1,0)) -> 1.5303244 | U11: 1.9631862 | V11: 2.6760446 | W11: 0.46683955
C12: %, улирлын (QoQ @ar) | H12: =Q12 -> 7.852745 | I12: =R12 -> 10.704179 | J12: =S12 -> 1.5303244 | L12: usd_mnt_qoq | M12: =INDEX(m!$B$2:$AY$51,MATCH(table!$L12,m!$A$2:$A$51,0),MATCH(table!M$4,m!$B$1:$AY$1,0)) -> 0.01965464 | N12: =INDEX(m!$B$2:$AY$51,MATCH(table!$L12,m!$A$2:$A$51,0),MATCH(table!N$4,m!$B$1:$AY$1,0)) -> 13.390859 | O12: =INDEX(m!$B$2:$AY$51,MATCH(table!$L12,m!$A$2:$A$51,0),MATCH(table!O$4,m!$B$1:$AY$1,0)) -> -5.6435901 | P12: =INDEX(m!$B$2:$AY$51,MATCH(table!$L12,m!$A$2:$A$51,0),MATCH(table!P$4,m!$B$1:$AY$1,0)) -> 4.6768197 | Q12: =INDEX(m!$B$2:$AY$51,MATCH(table!$L12,m!$A$2:$A$51,0),MATCH(table!Q$4,m!$B$1:$AY$1,0)) -> 7.852745 | R12: =INDEX(m!$B$2:$AY$51,MATCH(table!$L12,m!$A$2:$A$51,0),MATCH(table!R$4,m!$B$1:$AY$1,0)) -> 10.704179 | S12: =INDEX(m!$B$2:$AY$51,MATCH(table!$L12,m!$A$2:$A$51,0),MATCH(table!S$4,m!$B$1:$AY$1,0)) -> 1.5303244 | U12: 0.60723022 | V12: 0.19558192 | W12: 0.18291287
B13: Хятадын юань | D13: =M13 -> 446.96 | E13: =N13 -> 495.4 | F13: =O13 -> 480.01 | G13: =P13 -> 468.6 | H13: =Q13 -> 480.91 | I13: =R13 -> 499.76 | J13: =S13 -> 505.01 | L13: cny_mnt | M13: =INDEX(m!$B$2:$AY$51,MATCH(table!$L13,m!$A$2:$A$51,0),MATCH(table!M$4,m!$B$1:$AY$1,0)) -> 446.96 | N13: =INDEX(m!$B$2:$AY$51,MATCH(table!$L13,m!$A$2:$A$51,0),MATCH(table!N$4,m!$B$1:$AY$1,0)) -> 495.4 | O13: =INDEX(m!$B$2:$AY$51,MATCH(table!$L13,m!$A$2:$A$51,0),MATCH(table!O$4,m!$B$1:$AY$1,0)) -> 480.01 | P13: =INDEX(m!$B$2:$AY$51,MATCH(table!$L13,m!$A$2:$A$51,0),MATCH(table!P$4,m!$B$1:$AY$1,0)) -> 468.6 | Q13: =INDEX(m!$B$2:$AY$51,MATCH(table!$L13,m!$A$2:$A$51,0),MATCH(table!Q$4,m!$B$1:$AY$1,0)) -> 480.91 | R13: =INDEX(m!$B$2:$AY$51,MATCH(table!$L13,m!$A$2:$A$51,0),MATCH(table!R$4,m!$B$1:$AY$1,0)) -> 499.76 | S13: =INDEX(m!$B$2:$AY$51,MATCH(table!$L13,m!$A$2:$A$51,0),MATCH(table!S$4,m!$B$1:$AY$1,0)) -> 505.01 | U13: 480.91 | V13: 499.76 | W13: 498.81
C14: %, жилийн (YoY) | D14: =M14 -> 2.4597116 | E14: =N14 -> 10.837659 | F14: =O14 -> -3.1065805 | G14: =P14 -> -2.3770338 | H14: =Q14 -> 2.9102737 | I14: =R14 -> 7.4429204 | J14: =S14 -> 4.7521261 | L14: cny_mnt_yoy | M14: =INDEX(m!$B$2:$AY$51,MATCH(table!$L14,m!$A$2:$A$51,0),MATCH(table!M$4,m!$B$1:$AY$1,0)) -> 2.4597116 | N14: =INDEX(m!$B$2:$AY$51,MATCH(table!$L14,m!$A$2:$A$51,0),MATCH(table!N$4,m!$B$1:$AY$1,0)) -> 10.837659 | O14: =INDEX(m!$B$2:$AY$51,MATCH(table!$L14,m!$A$2:$A$51,0),MATCH(table!O$4,m!$B$1:$AY$1,0)) -> -3.1065805 | P14: =INDEX(m!$B$2:$AY$51,MATCH(table!$L14,m!$A$2:$A$51,0),MATCH(table!P$4,m!$B$1:$AY$1,0)) -> -2.3770338 | Q14: =INDEX(m!$B$2:$AY$51,MATCH(table!$L14,m!$A$2:$A$51,0),MATCH(table!Q$4,m!$B$1:$AY$1,0)) -> 2.9102737 | R14: =INDEX(m!$B$2:$AY$51,MATCH(table!$L14,m!$A$2:$A$51,0),MATCH(table!R$4,m!$B$1:$AY$1,0)) -> 7.4429204 | S14: =INDEX(m!$B$2:$AY$51,MATCH(table!$L14,m!$A$2:$A$51,0),MATCH(table!S$4,m!$B$1:$AY$1,0)) -> 4.7521261 | U14: 2.9102737 | V14: 7.4429204 | W14: 6.5537351
C15: %, улирлын (QoQ) | I15: =R15 -> 15.678609 | J15: =S15 -> 4.202017 | L15: cny_mnt_qoq | M15: =INDEX(m!$B$2:$AY$51,MATCH(table!$L15,m!$A$2:$A$51,0),MATCH(table!M$4,m!$B$1:$AY$1,0)) -> 5.5898367 | N15: =INDEX(m!$B$2:$AY$51,MATCH(table!$L15,m!$A$2:$A$51,0),MATCH(table!N$4,m!$B$1:$AY$1,0)) -> 28.40774 | O15: =INDEX(m!$B$2:$AY$51,MATCH(table!$L15,m!$A$2:$A$51,0),MATCH(table!O$4,m!$B$1:$AY$1,0)) -> 5.2341656 | P15: =INDEX(m!$B$2:$AY$51,MATCH(table!$L15,m!$A$2:$A$51,0),MATCH(table!P$4,m!$B$1:$AY$1,0)) -> -11.200996 | Q15: =INDEX(m!$B$2:$AY$51,MATCH(table!$L15,m!$A$2:$A$51,0),MATCH(table!Q$4,m!$B$1:$AY$1,0)) -> 10.507896 | R15: =INDEX(m!$B$2:$AY$51,MATCH(table!$L15,m!$A$2:$A$51,0),MATCH(table!R$4,m!$B$1:$AY$1,0)) -> 15.678609 | S15: =INDEX(m!$B$2:$AY$51,MATCH(table!$L15,m!$A$2:$A$51,0),MATCH(table!S$4,m!$B$1:$AY$1,0)) -> 4.202017 | U15: 2.626974 | V15: 3.9196523 | W15: 1.4707677
C16: %, улирлын (QoQ @ar) | H16: =Q16 -> 10.507896 | I16: =R16 -> 15.678609 | J16: =S16 -> 4.202017 | L16: cny_mnt_qoq | M16: =INDEX(m!$B$2:$AY$51,MATCH(table!$L16,m!$A$2:$A$51,0),MATCH(table!M$4,m!$B$1:$AY$1,0)) -> 5.5898367 | N16: =INDEX(m!$B$2:$AY$51,MATCH(table!$L16,m!$A$2:$A$51,0),MATCH(table!N$4,m!$B$1:$AY$1,0)) -> 28.40774 | O16: =INDEX(m!$B$2:$AY$51,MATCH(table!$L16,m!$A$2:$A$51,0),MATCH(table!O$4,m!$B$1:$AY$1,0)) -> 5.2341656 | P16: =INDEX(m!$B$2:$AY$51,MATCH(table!$L16,m!$A$2:$A$51,0),MATCH(table!P$4,m!$B$1:$AY$1,0)) -> -11.200996 | Q16: =INDEX(m!$B$2:$AY$51,MATCH(table!$L16,m!$A$2:$A$51,0),MATCH(table!Q$4,m!$B$1:$AY$1,0)) -> 10.507896 | R16: =INDEX(m!$B$2:$AY$51,MATCH(table!$L16,m!$A$2:$A$51,0),MATCH(table!R$4,m!$B$1:$AY$1,0)) -> 15.678609 | S16: =INDEX(m!$B$2:$AY$51,MATCH(table!$L16,m!$A$2:$A$51,0),MATCH(table!S$4,m!$B$1:$AY$1,0)) -> 4.202017 | U16: 1.0527422 | V16: 0.62822165 | W16: -0.19009124
B17: Бодлогын хүү | C17: %, жилийн | D17: =M17 -> 6 | E17: =N17 -> 13 | F17: =O17 -> 13 | G17: =P17 -> 10 | H17: =Q17 -> 11.715064 | I17: =R17 -> 12 | J17: =S17 -> 12 | L17: rate_pol | M17: =INDEX(m!$B$2:$AY$51,MATCH(table!$L17,m!$A$2:$A$51,0),MATCH(table!M$4,m!$B$1:$AY$1,0)) -> 6 | N17: =INDEX(m!$B$2:$AY$51,MATCH(table!$L17,m!$A$2:$A$51,0),MATCH(table!N$4,m!$B$1:$AY$1,0)) -> 13 | O17: =INDEX(m!$B$2:$AY$51,MATCH(table!$L17,m!$A$2:$A$51,0),MATCH(table!O$4,m!$B$1:$AY$1,0)) -> 13 | P17: =INDEX(m!$B$2:$AY$51,MATCH(table!$L17,m!$A$2:$A$51,0),MATCH(table!P$4,m!$B$1:$AY$1,0)) -> 10 | Q17: =INDEX(m!$B$2:$AY$51,MATCH(table!$L17,m!$A$2:$A$51,0),MATCH(table!Q$4,m!$B$1:$AY$1,0)) -> 11.715064 | R17: =INDEX(m!$B$2:$AY$51,MATCH(table!$L17,m!$A$2:$A$51,0),MATCH(table!R$4,m!$B$1:$AY$1,0)) -> 12 | S17: =INDEX(m!$B$2:$AY$51,MATCH(table!$L17,m!$A$2:$A$51,0),MATCH(table!S$4,m!$B$1:$AY$1,0)) -> 12 | U17: 11.715064 | V17: 12 | W17: 12
B18: Хадгаламжийн хүү | C18: %, шинэ, хуг-тай, банк | D18: =M18 -> 6.2153547 | E18: =N18 -> 11.083484 | F18: =O18 -> 11.789334 | G18: =P18 -> 12.1318 | H18: =Q18 -> 11.79411 | I18: =R18 -> 12.154919 | J18: =S18 -> 12.205959 | L18: rate_timedepo_mnt_new | M18: =INDEX(m!$B$2:$AY$51,MATCH(table!$L18,m!$A$2:$A$51,0),MATCH(table!M$4,m!$B$1:$AY$1,0)) -> 6.2153547 | N18: =INDEX(m!$B$2:$AY$51,MATCH(table!$L18,m!$A$2:$A$51,0),MATCH(table!N$4,m!$B$1:$AY$1,0)) -> 11.083484 | O18: =INDEX(m!$B$2:$AY$51,MATCH(table!$L18,m!$A$2:$A$51,0),MATCH(table!O$4,m!$B$1:$AY$1,0)) -> 11.789334 | P18: =INDEX(m!$B$2:$AY$51,MATCH(table!$L18,m!$A$2:$A$51,0),MATCH(table!P$4,m!$B$1:$AY$1,0)) -> 12.1318 | Q18: =INDEX(m!$B$2:$AY$51,MATCH(table!$L18,m!$A$2:$A$51,0),MATCH(table!Q$4,m!$B$1:$AY$1,0)) -> 11.79411 | R18: =INDEX(m!$B$2:$AY$51,MATCH(table!$L18,m!$A$2:$A$51,0),MATCH(table!R$4,m!$B$1:$AY$1,0)) -> 12.154919 | S18: =INDEX(m!$B$2:$AY$51,MATCH(table!$L18,m!$A$2:$A$51,0),MATCH(table!S$4,m!$B$1:$AY$1,0)) -> 12.205959 | U18: 16.953088 | V18: 17.27256 | W18: 17.09868
B19: Зээлийн хүү | C19: %, шинэ, банк | D19: =M19 -> 14.286499 | E19: =N19 -> 15.715657 | F19: =O19 -> 16.738576 | G19: =P19 -> 16.912679 | H19: =Q19 -> 16.953088 | I19: =R19 -> 17.27256 | J19: =S19 -> 17.260008 | L19: rate_loan_mnt_new | M19: =INDEX(m!$B$2:$AY$51,MATCH(table!$L19,m!$A$2:$A$51,0),MATCH(table!M$4,m!$B$1:$AY$1,0)) -> 14.286499 | N19: =INDEX(m!$B$2:$AY$51,MATCH(table!$L19,m!$A$2:$A$51,0),MATCH(table!N$4,m!$B$1:$AY$1,0)) -> 15.715657 | O19: =INDEX(m!$B$2:$AY$51,MATCH(table!$L19,m!$A$2:$A$51,0),MATCH(table!O$4,m!$B$1:$AY$1,0)) -> 16.738576 | P19: =INDEX(m!$B$2:$AY$51,MATCH(table!$L19,m!$A$2:$A$51,0),MATCH(table!P$4,m!$B$1:$AY$1,0)) -> 16.912679 | Q19: =INDEX(m!$B$2:$AY$51,MATCH(table!$L19,m!$A$2:$A$51,0),MATCH(table!Q$4,m!$B$1:$AY$1,0)) -> 16.953088 | R19: =INDEX(m!$B$2:$AY$51,MATCH(table!$L19,m!$A$2:$A$51,0),MATCH(table!R$4,m!$B$1:$AY$1,0)) -> 17.27256 | S19: =INDEX(m!$B$2:$AY$51,MATCH(table!$L19,m!$A$2:$A$51,0),MATCH(table!S$4,m!$B$1:$AY$1,0)) -> 17.260008 | U19: 11.79411 | V19: 12.154919 | W19: 11.664904
B20: Мөнгөний нийлүүлэлт | C20: %, жилийн (YoY) | D20: =M20 -> 13.817915 | E20: =N20 -> 6.4648482 | F20: =O20 -> 26.830692 | G20: =P20 -> 15.176127 | H20: =Q20 -> 10.917553 | I20: =R20 -> 3.694507 | J20: =S20 -> 5.5599996 | L20: ms_m2_yoy | M20: =INDEX(m!$B$2:$AY$51,MATCH(table!$L20,m!$A$2:$A$51,0),MATCH(table!M$4,m!$B$1:$AY$1,0)) -> 13.817915 | N20: =INDEX(m!$B$2:$AY$51,MATCH(table!$L20,m!$A$2:$A$51,0),MATCH(table!N$4,m!$B$1:$AY$1,0)) -> 6.4648482 | O20: =INDEX(m!$B$2:$AY$51,MATCH(table!$L20,m!$A$2:$A$51,0),MATCH(table!O$4,m!$B$1:$AY$1,0)) -> 26.830692 | P20: =INDEX(m!$B$2:$AY$51,MATCH(table!$L20,m!$A$2:$A$51,0),MATCH(table!P$4,m!$B$1:$AY$1,0)) -> 15.176127 | Q20: =INDEX(m!$B$2:$AY$51,MATCH(table!$L20,m!$A$2:$A$51,0),MATCH(table!Q$4,m!$B$1:$AY$1,0)) -> 10.917553 | R20: =INDEX(m!$B$2:$AY$51,MATCH(table!$L20,m!$A$2:$A$51,0),MATCH(table!R$4,m!$B$1:$AY$1,0)) -> 3.694507 | S20: =INDEX(m!$B$2:$AY$51,MATCH(table!$L20,m!$A$2:$A$51,0),MATCH(table!S$4,m!$B$1:$AY$1,0)) -> 5.5599996 | U20: 10.917553 | V20: 3.694507 | W20: 3.1831038
C21: %, улирлын (QoQ @ar) | I21: =R21 -> 14.61722 | J21: =S21 -> 10.489942 | L21: ms_m2_qoq | M21: =INDEX(m!$B$2:$AY$51,MATCH(table!$L21,m!$A$2:$A$51,0),MATCH(table!M$4,m!$B$1:$AY$1,0)) -> 8.8922852 | N21: =INDEX(m!$B$2:$AY$51,MATCH(table!$L21,m!$A$2:$A$51,0),MATCH(table!N$4,m!$B$1:$AY$1,0)) -> 32.068315 | O21: =INDEX(m!$B$2:$AY$51,MATCH(table!$L21,m!$A$2:$A$51,0),MATCH(table!O$4,m!$B$1:$AY$1,0)) -> 53.155141 | P21: =INDEX(m!$B$2:$AY$51,MATCH(table!$L21,m!$A$2:$A$51,0),MATCH(table!P$4,m!$B$1:$AY$1,0)) -> 14.651926 | Q21: =INDEX(m!$B$2:$AY$51,MATCH(table!$L21,m!$A$2:$A$51,0),MATCH(table!Q$4,m!$B$1:$AY$1,0)) -> -17.081982 | R21: =INDEX(m!$B$2:$AY$51,MATCH(table!$L21,m!$A$2:$A$51,0),MATCH(table!R$4,m!$B$1:$AY$1,0)) -> 14.61722 | S21: =INDEX(m!$B$2:$AY$51,MATCH(table!$L21,m!$A$2:$A$51,0),MATCH(table!S$4,m!$B$1:$AY$1,0)) -> 10.489942 | U21: -4.2704954 | V21: 3.6543051 | W21: 3.7934651
C22: Дүн, их наяд төг. | D22: =M22 -> 27.863477 | E22: =N22 -> 29.664808 | F22: =O22 -> 37.624081 | G22: =P22 -> 43.33396 | H22: =Q22 -> 41.483385 | I22: =R22 -> 42.999314 | J22: =S22 -> 44.126965 | L22: ms_m2 | M22: =INDEX(m!$B$2:$AY$51,MATCH(table!$L22,m!$A$2:$A$51,0),MATCH(table!M$4,m!$B$1:$AY$1,0)) -> 27.863477 | N22: =INDEX(m!$B$2:$AY$51,MATCH(table!$L22,m!$A$2:$A$51,0),MATCH(table!N$4,m!$B$1:$AY$1,0)) -> 29.664808 | O22: =INDEX(m!$B$2:$AY$51,MATCH(table!$L22,m!$A$2:$A$51,0),MATCH(table!O$4,m!$B$1:$AY$1,0)) -> 37.624081 | P22: =INDEX(m!$B$2:$AY$51,MATCH(table!$L22,m!$A$2:$A$51,0),MATCH(table!P$4,m!$B$1:$AY$1,0)) -> 43.33396 | Q22: =INDEX(m!$B$2:$AY$51,MATCH(table!$L22,m!$A$2:$A$51,0),MATCH(table!Q$4,m!$B$1:$AY$1,0)) -> 41.483385 | R22: =INDEX(m!$B$2:$AY$51,MATCH(table!$L22,m!$A$2:$A$51,0),MATCH(table!R$4,m!$B$1:$AY$1,0)) -> 42.999314 | S22: =INDEX(m!$B$2:$AY$51,MATCH(table!$L22,m!$A$2:$A$51,0),MATCH(table!S$4,m!$B$1:$AY$1,0)) -> 44.126965 | U22: 41.483385 | V22: 42.999314 | W22: 43.083566
C23: %, ДНБ харьцах | D23: =M23 -> 63.972372 | E23: =N23 -> 55.086272 | F23: =O23 -> 53.4118 | G23: =P23 -> 53.722193 | H23: =Q23 -> 50.887918 | I23: =R23 -> 51.238495 | J23: =J22/J62*100 -> 54.130814 | L23: m2_gdp | M23: =INDEX(m!$B$2:$AY$51,MATCH(table!$L23,m!$A$2:$A$51,0),MATCH(table!M$4,m!$B$1:$AY$1,0)) -> 63.972372 | N23: =INDEX(m!$B$2:$AY$51,MATCH(table!$L23,m!$A$2:$A$51,0),MATCH(table!N$4,m!$B$1:$AY$1,0)) -> 55.086272 | O23: =INDEX(m!$B$2:$AY$51,MATCH(table!$L23,m!$A$2:$A$51,0),MATCH(table!O$4,m!$B$1:$AY$1,0)) -> 53.4118 | P23: =INDEX(m!$B$2:$AY$51,MATCH(table!$L23,m!$A$2:$A$51,0),MATCH(table!P$4,m!$B$1:$AY$1,0)) -> 53.722193 | Q23: =INDEX(m!$B$2:$AY$51,MATCH(table!$L23,m!$A$2:$A$51,0),MATCH(table!Q$4,m!$B$1:$AY$1,0)) -> 50.887918 | R23: =INDEX(m!$B$2:$AY$51,MATCH(table!$L23,m!$A$2:$A$51,0),MATCH(table!R$4,m!$B$1:$AY$1,0)) -> 51.238495 | S23: =INDEX(m!$B$2:$AY$51,MATCH(table!$L23,m!$A$2:$A$51,0),MATCH(table!S$4,m!$B$1:$AY$1,0)) -> 51.696158 | U23: 50.307353
B24: Банкны зээл | C24: %, жилийн (YoY) | D24: =M24 -> 21.856801 | E24: =N24 -> 8.326797 | F24: =O24 -> 21.879296 | G24: =P24 -> 34.61869 | H24: =Q24 -> 32.779266 | I24: =R24 -> 27.109139 | J24: =S24 -> 22.760333 | L24: bank_ass_credit_nfi_yoy | M24: =INDEX(m!$B$2:$AY$51,MATCH(table!$L24,m!$A$2:$A$51,0),MATCH(table!M$4,m!$B$1:$AY$1,0)) -> 21.856801 | N24: =INDEX(m!$B$2:$AY$51,MATCH(table!$L24,m!$A$2:$A$51,0),MATCH(table!N$4,m!$B$1:$AY$1,0)) -> 8.326797 | O24: =INDEX(m!$B$2:$AY$51,MATCH(table!$L24,m!$A$2:$A$51,0),MATCH(table!O$4,m!$B$1:$AY$1,0)) -> 21.879296 | P24: =INDEX(m!$B$2:$AY$51,MATCH(table!$L24,m!$A$2:$A$51,0),MATCH(table!P$4,m!$B$1:$AY$1,0)) -> 34.61869 | Q24: =INDEX(m!$B$2:$AY$51,MATCH(table!$L24,m!$A$2:$A$51,0),MATCH(table!Q$4,m!$B$1:$AY$1,0)) -> 32.779266 | R24: =INDEX(m!$B$2:$AY$51,MATCH(table!$L24,m!$A$2:$A$51,0),MATCH(table!R$4,m!$B$1:$AY$1,0)) -> 27.109139 | S24: =INDEX(m!$B$2:$AY$51,MATCH(table!$L24,m!$A$2:$A$51,0),MATCH(table!S$4,m!$B$1:$AY$1,0)) -> 22.760333 | U24: 32.779266 | V24: 27.109139 | W24: 27.384671
C25: %, улирлын (QoQ @ar) | H25: =Q25 -> 19.732671 | I25: =R25 -> 39.591237 | J25: =S25 -> 5.8031325 | L25: bank_ass_credit_nfi_qoq | M25: =INDEX(m!$B$2:$AY$51,MATCH(table!$L25,m!$A$2:$A$51,0),MATCH(table!M$4,m!$B$1:$AY$1,0)) -> 13.679303 | N25: =INDEX(m!$B$2:$AY$51,MATCH(table!$L25,m!$A$2:$A$51,0),MATCH(table!N$4,m!$B$1:$AY$1,0)) -> -6.8829885 | O25: =INDEX(m!$B$2:$AY$51,MATCH(table!$L25,m!$A$2:$A$51,0),MATCH(table!O$4,m!$B$1:$AY$1,0)) -> 19.694894 | P25: =INDEX(m!$B$2:$AY$51,MATCH(table!$L25,m!$A$2:$A$51,0),MATCH(table!P$4,m!$B$1:$AY$1,0)) -> 19.721123 | Q25: =INDEX(m!$B$2:$AY$51,MATCH(table!$L25,m!$A$2:$A$51,0),MATCH(table!Q$4,m!$B$1:$AY$1,0)) -> 19.732671 | R25: =INDEX(m!$B$2:$AY$51,MATCH(table!$L25,m!$A$2:$A$51,0),MATCH(table!R$4,m!$B$1:$AY$1,0)) -> 39.591237 | S25: =INDEX(m!$B$2:$AY$51,MATCH(table!$L25,m!$A$2:$A$51,0),MATCH(table!S$4,m!$B$1:$AY$1,0)) -> 5.8031325 | U25: 4.9331678 | V25: 9.8978094 | W25: 7.6359818 | AD25: =H22/H23*100 -> 81.519123
C26: Дүн, их наяд төг. | D26: =M26 -> 20.197435 | E26: =N26 -> 21.879234 | F26: =O26 -> 26.666257 | G26: =P26 -> 35.897765 | H26: =Q26 -> 37.668663 | I26: =R26 -> 41.397035 | J26: =S26 -> 41.997616 | L26: bank_ass_credit_nfi | M26: =INDEX(m!$B$2:$AY$51,MATCH(table!$L26,m!$A$2:$A$51,0),MATCH(table!M$4,m!$B$1:$AY$1,0)) -> 20.197435 | N26: =INDEX(m!$B$2:$AY$51,MATCH(table!$L26,m!$A$2:$A$51,0),MATCH(table!N$4,m!$B$1:$AY$1,0)) -> 21.879234 | O26: =INDEX(m!$B$2:$AY$51,MATCH(table!$L26,m!$A$2:$A$51,0),MATCH(table!O$4,m!$B$1:$AY$1,0)) -> 26.666257 | P26: =INDEX(m!$B$2:$AY$51,MATCH(table!$L26,m!$A$2:$A$51,0),MATCH(table!P$4,m!$B$1:$AY$1,0)) -> 35.897765 | Q26: =INDEX(m!$B$2:$AY$51,MATCH(table!$L26,m!$A$2:$A$51,0),MATCH(table!Q$4,m!$B$1:$AY$1,0)) -> 37.668663 | R26: =INDEX(m!$B$2:$AY$51,MATCH(table!$L26,m!$A$2:$A$51,0),MATCH(table!R$4,m!$B$1:$AY$1,0)) -> 41.397035 | S26: =INDEX(m!$B$2:$AY$51,MATCH(table!$L26,m!$A$2:$A$51,0),MATCH(table!S$4,m!$B$1:$AY$1,0)) -> 41.997616
C27: %, ДНБ харьцах | D27: =D26/D62*100 -> 46.377577 | E27: =E26/E62*100 -> 40.629961 | F27: =F26/F62*100 -> 37.856696 | G27: =G26/G62*100 -> 44.50504 | H27: =H26/H62*100 -> 46.208375 | I27: =I26/I62*100 -> 50.781992 | J27: =J26/J62*100 -> 51.518729 | L27: loan_gdp | M27: =INDEX(m!$B$2:$AY$51,MATCH(table!$L27,m!$A$2:$A$51,0),MATCH(table!M$4,m!$B$1:$AY$1,0)) -> 4.6371737e-05 | N27: =INDEX(m!$B$2:$AY$51,MATCH(table!$L27,m!$A$2:$A$51,0),MATCH(table!N$4,m!$B$1:$AY$1,0)) -> 4.0628796e-05 | O27: =INDEX(m!$B$2:$AY$51,MATCH(table!$L27,m!$A$2:$A$51,0),MATCH(table!O$4,m!$B$1:$AY$1,0)) -> 3.7855881e-05 | P27: =INDEX(m!$B$2:$AY$51,MATCH(table!$L27,m!$A$2:$A$51,0),MATCH(table!P$4,m!$B$1:$AY$1,0)) -> 4.4503357e-05 | Q27: =INDEX(m!$B$2:$AY$51,MATCH(table!$L27,m!$A$2:$A$51,0),MATCH(table!Q$4,m!$B$1:$AY$1,0)) -> 4.6208375e-05 | R27: =INDEX(m!$B$2:$AY$51,MATCH(table!$L27,m!$A$2:$A$51,0),MATCH(table!R$4,m!$B$1:$AY$1,0)) -> 4.93292e-05 | S27: =INDEX(m!$B$2:$AY$51,MATCH(table!$L27,m!$A$2:$A$51,0),MATCH(table!S$4,m!$B$1:$AY$1,0)) -> 4.9201557e-05 | U27: 45.681198
B28: Банкны зээл /иргэд/ | C28: %, жилийн (YoY) | D28: =M28 -> 21.788529 | E28: =N28 -> 11.139411 | F28: =O28 -> 32.454539 | G28: =P28 -> 42.418936 | H28: =Q28 -> 36.083349 | I28: =R28 -> 26.618682 | J28: =S28 -> 21.313132 | L28: dc_loan_ind_yoy | M28: =INDEX(m!$B$2:$AY$51,MATCH(table!$L28,m!$A$2:$A$51,0),MATCH(table!M$4,m!$B$1:$AY$1,0)) -> 21.788529 | N28: =INDEX(m!$B$2:$AY$51,MATCH(table!$L28,m!$A$2:$A$51,0),MATCH(table!N$4,m!$B$1:$AY$1,0)) -> 11.139411 | O28: =INDEX(m!$B$2:$AY$51,MATCH(table!$L28,m!$A$2:$A$51,0),MATCH(table!O$4,m!$B$1:$AY$1,0)) -> 32.454539 | P28: =INDEX(m!$B$2:$AY$51,MATCH(table!$L28,m!$A$2:$A$51,0),MATCH(table!P$4,m!$B$1:$AY$1,0)) -> 42.418936 | Q28: =INDEX(m!$B$2:$AY$51,MATCH(table!$L28,m!$A$2:$A$51,0),MATCH(table!Q$4,m!$B$1:$AY$1,0)) -> 36.083349 | R28: =INDEX(m!$B$2:$AY$51,MATCH(table!$L28,m!$A$2:$A$51,0),MATCH(table!R$4,m!$B$1:$AY$1,0)) -> 26.618682 | S28: =INDEX(m!$B$2:$AY$51,MATCH(table!$L28,m!$A$2:$A$51,0),MATCH(table!S$4,m!$B$1:$AY$1,0)) -> 21.313132 | U28: 36.083349 | V28: 26.618682 | W28: 27.245572 | AD28: =H27*$AD$25/100 -> 37.668663 | AE28: =AD28*(1+#REF!/100) -> #REF! | AF28: =AE28*(1+#REF!/100) -> #REF!
